Workbook
Name __?춮tb: #REF!
Name ___________________A19999: #REF!
Name ___________________A20000: #REF!
Name ___________________A99999: #REF!
Name ___________________ZZ16384: #REF!
Name __________________A19999: #REF!
Name __________________A20000: #REF!
Name __________________A99999: #REF!
Name __________________ZZ16384: #REF!
Name _________________A19999: #REF!
Name _________________A20000: #REF!
Name _________________A99999: #REF!
Name _________________ZZ16384: #REF!
Name ________________A19999: #REF!
Name ________________A20000: #REF!
Name ________________A99999: #REF!
Name ________________ZZ16384: #REF!
Name _______________A19999: #REF!
Name _______________A20000: #REF!
Name _______________A99999: #REF!
Name _______________ZZ16384: #REF!
Name ______________A19999: #REF!
Name ______________A20000: #REF!
Name ______________A99999: #REF!
Name ______________ZZ16384: #REF!
Name _____________A19999: #REF!
Name _____________A20000: #REF!
Name _____________A99999: #REF!
Name _____________ZZ16384: #REF!
Name ____________A19999: #REF!
Name ____________A20000: #REF!
Name ____________A99999: #REF!
Name ____________ZZ16384: #REF!
Name ___________A19999: #REF!
Name ___________A20000: #REF!
Name _______A19999: #REF!
Name _______A20000: #REF!
Name _______A99999: #REF!
Name _______ZZ16384: #REF!
Name _____A99999: #REF!
Name _____ZZ16384: #REF!
Name ____A19999: #REF!
Name ____A20000: #REF!
Name ____A99999: #REF!
Name ____ZZ16384: #REF!
Name ___A19999: #REF!
Name ___A20000: #REF!
Name ___A99999: #REF!
Name ___ZZ16384: #REF!
Name __0: #REF!
Name __01: #REF!
Name __02: #REF!
Name __03: #REF!
Name __04: #REF!
Name __05: #REF!
Name __06: #REF!
Name __A19999: #N/A
Name __A20000: #N/A
Name __Ａ４: #REF!
Name __A99999: #REF!

Sheet 요약
T1: 1W | U1: 2W | V1: 3W | W1: 4W | X1: 5W
R2: =Q2/Q8 -> 0 | Z2: 동요일 | AA2: 동요일 | AB2: 동요일 | AC2: 동요일 | AD2: 동요일
Q3: 동일자
E4: MLB | H4: 11월 | I4: Actual + Forward FCST | Z4: Lsat Year | AU4: 수식
H5: TARGET | I5: Sales FCST | K5: LY ACTUAL월마감 | L5: GR | M5: Latest FCST | Q5: Actual MTD | R5: LY ACTUAL | S5: GR | T5: Actual | U5: Actual | V5: Actual | W5: Actual | X5: FCST | Z5: LY | AE5: diff (+/-) vs LY | AJ5: Gr.
I6: Sales AMT | J6: Ach% | K6: SALES | L6: vs LY | M6: Sales AMT | N6: DIFF | O6: 주간 | P6: DIFF | T6: W44 (11.1~2) | U6: W45 (11.3~9) | V6: W46 (11.10~16) | W6: W47 (11.17~23) | X6: W48 (11.24~30) | Z6: W44 (11.2~3) | AA6: W45 (11.4~10) | AB6: W46 (11.11~17) | AC6: W47 (11.18~24) | AD6: W48 (11.25~12.1) | AE6: W40 | AF6: W41 | AG6: W42 | AH6: W43 | AI6: W44 | AJ6: W44 | AK6: W45 | AL6: W46 | AM6: W47 | AN6: W48
C7: =H7/K7-1 -> 0.06424192 | E7: 상권 | G7: SUM | H7: =SUM(H8,H11,H13,H12) -> 33000000000 | I7: =SUM(I8,I11,I13,I12) -> 33686756220 | J7: =IFERROR(I7/$H7,"") -> 1.0208108 | K7: =SUM(K8,K11,K13,K12) -> 31007987365 | L7: =IFERROR(I7/K7-1,"") -> 0.08638964 | M7: 33558797360 | N7: =IFERROR(M7-I7,"") -> -127958860 | O7: 7686811403 | P7: =IFERROR(W7-O7,"") -> 127958860 | Q7: =SUM(Q8,Q11,Q13)+Q12 -> 25901904597 | R7: =SUM(R8,R11,R13)+R12 -> 23809938360 | S7: =IFERROR(Q7/R7-1,"") -> 0.087861052 | T7: =SUM(T8,T11,T13)+T12 -> 3080371793 | U7: =SUM(U8,U11,U13)+U12 -> 7723410468 | V7: =SUM(V8,V11,V13)+V12 -> 7283352073 | W7: =SUM(W8,W11,W13)+W12 -> 7814770263 | X7: =SUM(X8,X11,X13)+X12 -> 7784851623 | Z7: =SUM(Z8,Z11,Z12,Z13) -> 2007969322 | AA7: =SUM(AA8,AA11,AA12,AA13) -> 7740086118 | AB7: =SUM(AB8,AB11,AB12,AB13) -> 6993007565 | AC7: =SUM(AC8,AC11,AC12,AC13) -> 7212765468 | AD7: =SUM(AD8,AD11,AD12,AD13) -> 7166784270 | AE7: =IFERROR(T7-Z7,"") -> 1072402471 | AF7: =IFERROR(U7-AA7,"") -> -16675650 | AG7: =IFERROR(V7-AB7,"") -> 290344508 | AH7: =IFERROR(W7-AC7,"") -> 602004795 | AI7: =IFERROR(X7-AD7,"") -> 618067353 | AJ7: =IFERROR(T7/Z7-1,"") -> 0.53407314 | AK7: =IFERROR(U7/AA7-1,"") -> -0.0021544528 | AL7: =IFERROR(V7/AB7-1,"") -> 0.041519261 | AM7: =IFERROR(W7/AC7-1,"") -> 0.083463797 | AN7: =IFERROR(X7/AD7-1,"") -> 0.086240541 | AU7: =SUM(AU8,AU11,AU13)+AU12 -> 0
B8: 국내 | C8: =H8/K8-1 -> 0.066193527 | G8: 국내 | H8: =SUM(H9:H10) -> 18249000000 | I8: =SUM(T8,U8,V8,W8,X8) -> 19080059720 | J8: =IFERROR(I8/$H8,"") -> 1.04554 | K8: =SUM(K9:K10) -> 17116029629 | L8: =IFERROR(I8/K8-1,"") -> 0.114748 | M8: 19020314207 | N8: =IFERROR(M8-I8,"") -> -59745513 | O8: 4397800000 | P8: =IFERROR(W8-O8,"") -> 59745513 | Q8: =SUM(Q9:Q10) -> 14335259720 | R8: =SUM(R9:R10) -> 12988923264 | S8: =IFERROR(Q8/R8-1,"") -> 0.10365266 | T8: =SUM(T9:T10) -> 2057056396 | U8: =SUM(U9:U10) -> 4109710148 | V8: =SUM(V9:V10) -> 3710947663 | W8: =SUM(W9:W10) -> 4457545513 | X8: =SUM(X9:X10) -> 4744800000 | Z8: =SUM(Z9:Z10) -> 1142785422 | AA8: =SUM(AA9:AA10) -> 4066843012 | AB8: =SUM(AB9:AB10) -> 3746477935 | AC8: =SUM(AC9:AC10) -> 4412933708 | AD8: =SUM(AD9:AD10) -> 4141793510 | AE8: =IFERROR(T8-Z8,"") -> 914270974 | AF8: =IFERROR(U8-AA8,"") -> 42867136 | AG8: =IFERROR(V8-AB8,"") -> -35530272 | AH8: =IFERROR(W8-AC8,"") -> 44611805 | AI8: =IFERROR(X8-AD8,"") -> 603006490 | AJ8: =IFERROR(T8/Z8-1,"") -> 0.80003731 | AK8: =IFERROR(U8/AA8-1,"") -> 0.010540642 | AL8: =IFERROR(V8/AB8-1,"") -> -0.0094836464 | AM8: =IFERROR(W8/AC8-1,"") -> 0.01010933 | AN8: =IFERROR(X8/AD8-1,"") -> 0.14559067 | AU8: =SUM(AU9:AU10) -> 0
G9: 국내(순수) | H9: =SUM(H32,H35,H39,H41,H37) -> 13309000000 | I9: =SUM(T9,U9,V9,W9,X9) -> 13772469070 | J9: =IFERROR(I9/$H9,"") -> 1.0348237 | K9: =SUM(K32,K35,K39,K41,K37) -> 14487407654 | L9: =IFERROR(I9/K9-1,"") -> -0.049348966 | M9: 14029877545 | N9: =IFERROR(M9-I9,"") -> 257408475 | O9: 3632300000 | P9: =IFERROR(W9-O9,"") -> -257408475 | Q9: =SUM(Q32,Q35,Q39,Q41,Q37) -> 10279169070 | R9: =SUM(R32,R35,R39,R41,R37) -> 10794634811 | S9: =IFERROR(Q9/R9-1,"") -> -0.047752031 | T9: =SUM(T32,T35,T39,T41,T37) -> 1268310918 | U9: =SUM(U32,U35,U39,U41,U37) -> 2753223784 | V9: =SUM(V32,V35,V39,V41,V37) -> 2882742843 | W9: =SUM(W32,W35,W39,W41,W37) -> 3374891525 | X9: =SUM(X32,X35,X39,X41,X37) -> 3493300000 | Z9: =SUM(Z32,Z35,Z39,Z41,Z37) -> 8.1100466e+08 | AA9: =SUM(AA32,AA35,AA39,AA41,AA37) -> 2.7994019e+09 | AB9: =SUM(AB32,AB35,AB39,AB41,AB37) -> 2.6857768e+09 | AC9: =SUM(AC32,AC35,AC39,AC41,AC37) -> 3.3341285e+09 | AD9: =SUM(AD32,AD35,AD39,AD41,AD37) -> 3.3826155e+09 | AE9: =IFERROR(T9-Z9,"") -> 4.5730626e+08 | AF9: =IFERROR(U9-AA9,"") -> -46178091 | AG9: =IFERROR(V9-AB9,"") -> 1.96966e+08 | AH9: =IFERROR(W9-AC9,"") -> 40762978 | AI9: =IFERROR(X9-AD9,"") -> 1.1068447e+08 | AJ9: =IFERROR(T9/Z9-1,"") -> 0.56387623 | AK9: =IFERROR(U9/AA9-1,"") -> -0.016495699 | AL9: =IFERROR(V9/AB9-1,"") -> 0.073336697 | AM9: =IFERROR(W9/AC9-1,"") -> 0.012225977 | AN9: =IFERROR(X9/AD9-1,"") -> 0.032721563 | AU9: =SUM(AU32,AU35,AU39,AU41,AU37) -> 0
G10: 국내(단체) | H10: =SUM(H45,H48,H52,H54) -> 4940000000 | I10: =SUM(T10,U10,V10,W10,X10) -> 5307590650 | J10: =IFERROR(I10/$H10,"") -> 1.0744111 | K10: =SUM(K45,K48,K52,K54,K50) -> 2628621975 | L10: =IFERROR(I10/K10-1,"") -> 1.0191533 | M10: 4990436662 | N10: =IFERROR(M10-I10,"") -> -317153988 | O10: 765500000 | P10: =IFERROR(W10-O10,"") -> 317153988 | Q10: =SUM(Q45,Q48,Q52,Q54) -> 4056090650 | R10: =SUM(R45,R48,R52,R54) -> 2194288453 | S10: =IFERROR(Q10/R10-1,"") -> 0.8484765 | T10: =SUM(T45,T48,T52,T54,T50) -> 788745478 | U10: =SUM(U45,U48,U52,U54,U50) -> 1356486364 | V10: =SUM(V45,V48,V52,V54,V50) -> 828204820 | W10: =SUM(W45,W48,W52,W54,W50) -> 1082653988 | X10: =SUM(X45,X48,X52,X54,X50) -> 1251500000 | Z10: =SUM(Z45,Z48,Z52,Z54,Z50) -> 3.3178076e+08 | AA10: =SUM(AA45,AA48,AA52,AA54,AA50) -> 1.2674411e+09 | AB10: =SUM(AB45,AB48,AB52,AB54,AB50) -> 1.0607011e+09 | AC10: =SUM(AC45,AC48,AC52,AC54,AC50) -> 1.0788052e+09 | AD10: =SUM(AD45,AD48,AD52,AD54,AD50) -> 7.5917798e+08 | AE10: =IFERROR(T10-Z10,"") -> 4.5696472e+08 | AF10: =IFERROR(U10-AA10,"") -> 89045227 | AG10: =IFERROR(V10-AB10,"") -> -2.3249627e+08 | AH10: =IFERROR(W10-AC10,"") -> 3848827.5 | AI10: =IFERROR(X10-AD10,"") -> 4.9232202e+08 | AJ10: =IFERROR(T10/Z10-1,"") -> 1.3773093 | AK10: =IFERROR(U10/AA10-1,"") -> 0.070255907 | AL10: =IFERROR(V10/AB10-1,"") -> -0.21919113 | AM10: =IFERROR(W10/AC10-1,"") -> 0.0035676762 | AN10: =IFERROR(X10/AD10-1,"") -> 0.64849355 | AU10: =SUM(AU45,AU48,AU52,AU54,AU50) -> 0
A11: 파트너채널팀 | B11: 면세 | C11: =H11/K11-1 -> -0.028421824 | G11: 면세 | H11: 10600000000 | I11: =SUM(T11,U11,V11,W11,X11) -> 10456477100 | J11: =IFERROR(I11/$H11,"") -> 0.9864601 | K11: =SUMIFS(전년!$BD:$BD,전년!$A:$A,$A11,전년!$B:$B,요약!$B11) -> 10910084500 | L11: =IFERROR(I11/K11-1,"") -> -0.041576892 | M11: 10340000000 | N11: =IFERROR(M11-I11,"") -> -116477100 | O11: 2412000000 | P11: =IFERROR(W11-O11,"") -> 116477100 | Q11: =SUMIFS(당년!$BC:$BC,당년!$A:$A,요약!$A11,당년!$B:$B,요약!$B11) -> 8382056500 | R11: =SUMIFS(전년!$BC:$BC,전년!$A:$A,요약!$A11,전년!$B:$B,요약!$B11) -> 8486829900 | S11: =IFERROR(Q11/R11-1,"") -> -0.012345411 | T11: =SUMIFS(당년!AW:AW,당년!$A:$A,요약!$A11,당년!$B:$B,요약!$B11) -> 671832000 | U11: =SUMIFS(당년!AX:AX,당년!$A:$A,요약!$A11,당년!$B:$B,요약!$B11) -> 2533637300 | V11: =SUMIFS(당년!AY:AY,당년!$A:$A,요약!$A11,당년!$B:$B,요약!$B11) -> 2648110100 | W11: =SUMIFS(당년!AZ:AZ,당년!$A:$A,요약!$A11,당년!$B:$B,요약!$B11) -> 2528477100 | X11: 2074420600 | Z11: =SUMIFS(전년!AW:AW,전년!$A:$A,$A11,전년!$B:$B,$B11) -> 689328400 | AA11: =SUMIFS(전년!AX:AX,전년!$A:$A,$A11,전년!$B:$B,$B11) -> 2886112500 | AB11: =SUMIFS(전년!AY:AY,전년!$A:$A,$A11,전년!$B:$B,$B11) -> 2538642900 | AC11: =SUMIFS(전년!AZ:AZ,전년!$A:$A,$A11,전년!$B:$B,$B11) -> 2136325600 | AD11: =SUMIFS(전년!BA:BA,전년!$A:$A,$A11,전년!$B:$B,$B11) -> 2362900600 | AE11: =IFERROR(T11-Z11,"") -> -17496400 | AF11: =IFERROR(U11-AA11,"") -> -352475200 | AG11: =IFERROR(V11-AB11,"") -> 109467200 | AH11: =IFERROR(W11-AC11,"") -> 392151500 | AI11: =IFERROR(X11-AD11,"") -> -288480000 | AJ11: =IFERROR(T11/Z11-1,"") -> -0.025381806 | AK11: =IFERROR(U11/AA11-1,"") -> -0.12212802 | AL11: =IFERROR(V11/AB11-1,"") -> 0.043120362 | AM11: =IFERROR(W11/AC11-1,"") -> 0.18356354 | AN11: =IFERROR(X11/AD11-1,"") -> -0.12208723 | AU11: =SUMIFS(당년!BX:BX,당년!$A:$A,요약!$A11,당년!$B:$B,요약!$B11) -> 0
A12: 파트너채널팀 | B12: 도매 | C12: =H12/K12-1 -> -0.11099886 | G12: 도매 | H12: 250000000 | I12: =SUM(T12,U12,V12,W12,X12) -> 250000000 | J12: =IFERROR(I12/$H12,"") -> 1 | K12: =SUMIFS(전년!$BD:$BD,전년!$A:$A,$A12,전년!$B:$B,요약!$B12) -> 281214486 | L12: =IFERROR(I12/K12-1,"") -> -0.11099886 | M12: 250000000 | N12: =IFERROR(M12-I12,"") -> 0 | O12: 45085950 | P12: =IFERROR(W12-O12,"") -> 0 | Q12: =SUMIFS(당년!$BC:$BC,당년!$A:$A,요약!$A12,당년!$B:$B,요약!$B12) -> 194204430 | R12: =SUMIFS(전년!$BC:$BC,전년!$A:$A,요약!$A12,전년!$B:$B,요약!$B12) -> 217153566 | S12: =IFERROR(Q12/R12-1,"") -> -0.1056816 | T12: =SUMIFS(당년!AW:AW,당년!$A:$A,요약!$A12,당년!$B:$B,요약!$B12) -> 0 | U12: =SUMIFS(당년!AX:AX,당년!$A:$A,요약!$A12,당년!$B:$B,요약!$B12) -> 76939380 | V12: =SUMIFS(당년!AY:AY,당년!$A:$A,요약!$A12,당년!$B:$B,요약!$B12) -> 72179100 | W12: =SUMIFS(당년!AZ:AZ,당년!$A:$A,요약!$A12,당년!$B:$B,요약!$B12) -> 45085950 | X12: 55795570 | Z12: =SUMIFS(전년!AW:AW,전년!$A:$A,$A12,전년!$B:$B,$B12) -> 0 | AA12: =SUMIFS(전년!AX:AX,전년!$A:$A,$A12,전년!$B:$B,$B12) -> 116924976 | AB12: =SUMIFS(전년!AY:AY,전년!$A:$A,$A12,전년!$B:$B,$B12) -> 44497530 | AC12: =SUMIFS(전년!AZ:AZ,전년!$A:$A,$A12,전년!$B:$B,$B12) -> 55731060 | AD12: =SUMIFS(전년!BA:BA,전년!$A:$A,$A12,전년!$B:$B,$B12) -> 64060920 | AE12: =IFERROR(T12-Z12,"") -> 0 | AF12: =IFERROR(U12-AA12,"") -> -39985596 | AG12: =IFERROR(V12-AB12,"") -> 27681570 | AH12: =IFERROR(W12-AC12,"") -> -10645110 | AI12: =IFERROR(X12-AD12,"") -> -8265350 | AJ12: =IFERROR(T12/Z12-1,"") | AK12: =IFERROR(U12/AA12-1,"") -> -0.34197652 | AL12: =IFERROR(V12/AB12-1,"") -> 0.62209228 | AM12: =IFERROR(W12/AC12-1,"") -> -0.19100857 | AN12: =IFERROR(X12/AD12-1,"") -> -0.12902328 | AU12: =SUMIFS(당년!BX:BX,당년!$A:$A,요약!$A12,당년!$B:$B,요약!$B12) -> 0
B13: RF | C13: =H13/K13-1 -> 0.44446239 | G13: RF | H13: =SUM(H33,H36,H40,H46,H49,H53) -> 3901000000 | I13: =SUM(T13,U13,V13,W13,X13) -> 3900219400 | J13: =IFERROR(I13/$H13,"") -> 0.9997999 | K13: =SUM(K33,K36,K40,K46,K49,K53) -> 2700658750 | L13: =IFERROR(I13/K13-1,"") -> 0.44417335 | M13: 3948483153 | N13: =IFERROR(M13-I13,"") -> 48263753 | O13: 831925453 | P13: =IFERROR(W13-O13,"") -> -48263753 | Q13: =SUM(Q33,Q36,Q40,Q46,Q49,Q53) -> 2990383947 | R13: =SUM(R33,R36,R40,R46,R49,R53) -> 2117031630 | S13: =IFERROR(Q13/R13-1,"") -> 0.41253626 | T13: =SUM(T33,T36,T40,T46,T49,T53) -> 351483397 | U13: =SUM(U33,U36,U40,U46,U49,U53) -> 1003123640 | V13: =SUM(V33,V36,V40,V46,V49,V53) -> 852115210 | W13: =SUM(W33,W36,W40,W46,W49,W53) -> 783661700 | X13: =SUM(X33,X36,X40,X46,X49,X53) -> 909835453 | Z13: =SUM(Z33,Z36,Z40,Z46,Z49,Z53) -> 175855500 | AA13: =SUM(AA33,AA36,AA40,AA46,AA49,AA53) -> 670205630 | AB13: =SUM(AB33,AB36,AB40,AB46,AB49,AB53) -> 663389200 | AC13: =SUM(AC33,AC36,AC40,AC46,AC49,AC53) -> 607775100 | AD13: =SUM(AD33,AD36,AD40,AD46,AD49,AD53) -> 598029240 | AE13: =IFERROR(T13-Z13,"") -> 175627897 | AF13: =IFERROR(U13-AA13,"") -> 332918010 | AG13: =IFERROR(V13-AB13,"") -> 188726010 | AH13: =IFERROR(W13-AC13,"") -> 175886600 | AI13: =IFERROR(X13-AD13,"") -> 311806213 | AJ13: =IFERROR(T13/Z13-1,"") -> 0.99870574 | AK13: =IFERROR(U13/AA13-1,"") -> 0.4967401 | AL13: =IFERROR(V13/AB13-1,"") -> 0.28448761 | AM13: =IFERROR(W13/AC13-1,"") -> 0.28939422 | AN13: =IFERROR(X13/AD13-1,"") -> 0.52138958 | AU13: =SUM(AU33,AU36,AU40,AU46,AU49,AU53) -> 0
G14: 면세제외 | H14: =SUM(H8,H12:H13) -> 22400000000 | I14: =SUM(T14,U14,V14,W14,X14) -> 23230279120 | J14: =IFERROR(I14/$H14,"") -> 1.037066 | K14: =SUM(K8,K12:K13) -> 20097902865 | L14: =IFERROR(I14/K14-1,"") -> 0.15585588 | M14: 23218797360 | N14: =IFERROR(M14-I14,"") -> -11481760 | O14: 5274811403 | P14: =IFERROR(W14-O14,"") -> 11481760 | Q14: =SUM(Q8,Q13,Q12) -> 17519848097 | R14: =SUM(R8,R13,R12) -> 15323108460 | S14: =IFERROR(Q14/R14-1,"") -> 0.14336123 | T14: =SUM(T8,T13,T12) -> 2408539793 | U14: =SUM(U8,U13,U12) -> 5189773168 | V14: =SUM(V8,V13,V12) -> 4635241973 | W14: =SUM(W8,W13,W12) -> 5286293163 | X14: =SUM(X8,X13,X12) -> 5710431023 | Z14: =SUM(Z8,Z13) -> 1318640922 | AA14: =SUM(AA8,AA13) -> 4737048642 | AB14: =SUM(AB8,AB13) -> 4409867135 | AC14: =SUM(AC8,AC13) -> 5020708808 | AD14: =SUM(AD8,AD13) -> 4739822750 | AE14: =IFERROR(T14-Z14,"") -> 1089898871 | AF14: =IFERROR(U14-AA14,"") -> 452724526 | AG14: =IFERROR(V14-AB14,"") -> 225374838 | AH14: =IFERROR(W14-AC14,"") -> 265584355 | AI14: =IFERROR(X14-AD14,"") -> 970608273 | AJ14: =IFERROR(T14/Z14-1,"") -> 0.82653196 | AK14: =IFERROR(U14/AA14-1,"") -> 0.095571011 | AL14: =IFERROR(V14/AB14-1,"") -> 0.051106945 | AM14: =IFERROR(W14/AC14-1,"") -> 0.052897781 | AN14: =IFERROR(X14/AD14-1,"") -> 0.20477734 | AU14: =SUM(AU8,AU13,AU12) -> 0
P15: =IFERROR(W15-O15,"") -> 0
C16: =H16/K16-1 -> 0.06424192 | E16: TEAM | G16: SUM | H16: =SUM(H17:H19) -> 33000000000 | I16: =SUM(T16,U16,V16,W16,X16) -> 33662946220 | J16: =IFERROR(I16/$H16,"") -> 1.0200893 | K16: =SUM(K17:K19) -> 31007987365 | L16: =IFERROR(I16/K16-1,"") -> 0.085621773 | M16: 33534987360 | N16: =IFERROR(M16-I16,"") -> -127958860 | O16: 7686811403 | P16: =IFERROR(W16-O16,"") -> 127958860 | Q16: =SUM(Q17:Q19) -> 25901904597 | R16: =SUM(R17:R19) -> 23809938360 | S16: =IFERROR(Q16/R16-1,"") -> 0.087861052 | T16: =SUM(T17:T19) -> 3080371793 | U16: =SUM(U17:U19) -> 7723410468 | V16: =SUM(V17:V19) -> 7259542073 | W16: =SUM(W17:W19) -> 7814770263 | X16: =SUM(X17:X19) -> 7784851623 | Z16: =SUM(Z17:Z19) -> 2007969322 | AA16: =SUM(AA17:AA19) -> 7740086118 | AB16: =SUM(AB17:AB19) -> 6993007565 | AC16: =SUM(AC17:AC19) -> 7212765468 | AD16: =SUM(AD17:AD19) -> 7166784270 | AE16: =IFERROR(T16-Z16,"") -> 1072402471 | AF16: =IFERROR(U16-AA16,"") -> -16675650 | AG16: =IFERROR(V16-AB16,"") -> 266534508 | AH16: =IFERROR(W16-AC16,"") -> 602004795 | AI16: =IFERROR(X16-AD16,"") -> 618067353 | AJ16: =IFERROR(T16/Z16-1,"") -> 0.53407314 | AK16: =IFERROR(U16/AA16-1,"") -> -0.0021544528 | AL16: =IFERROR(V16/AB16-1,"") -> 0.038114432 | AM16: =IFERROR(W16/AC16-1,"") -> 0.083463797 | AN16: =IFERROR(X16/AD16-1,"") -> 0.086240541 | AP16: =SUM(AP17:AP19) -> 3571878354 | AQ16: =AP16-O16 -> -4114933049 | AU16: =SUM(AU17:AU19) -> 0
A17: 파트너채널팀 | C17: =H17/K17-1 -> 0.013989901 | G17: 파트너채널 | H17: =SUM(H31,H44,H11,H12) -> 19890000000 | I17: =SUM(T17,U17,V17,W17,X17) -> 20174598680 | J17: =IFERROR(I17/$H17,"") -> 1.0143086 | K17: =SUMIFS(전년!$BD:$BD,전년!$A:$A,$A17) -> 19615579976 | L17: =IFERROR(I17/K17-1,"") -> 0.028498709 | M17: 19757203980 | N17: =IFERROR(M17-I17,"") -> -417394700 | O17: 4167085950 | P17: =IFERROR(W17-O17,"") -> 417394700 | Q17: =SUM(Q31,Q44,Q11,Q12) -> 15528192510 | R17: =SUM(R31,R44,R11,R12) -> 15287054926 | S17: =IFERROR(Q17/R17-1,"") -> 0.015773972 | T17: =SUM(T31,T44,T11,T12) -> 1698857060 | U17: =SUM(U31,U44,U11,U12) -> 4825488500 | V17: =SUM(V31,V44,V11,V12) -> 4395556300 | W17: =SUM(W31,W44,W11,W12) -> 4584480650 | X17: =SUM(X31,X44,X11,X12) -> 4670216170 | Z17: =SUMIFS(전년!AW:AW,전년!$A:$A,$A17) -> 1319151530 | AA17: =SUMIFS(전년!AX:AX,전년!$A:$A,$A17) -> 5178967396 | AB17: =SUMIFS(전년!AY:AY,전년!$A:$A,$A17) -> 4536747490 | AC17: =SUMIFS(전년!AZ:AZ,전년!$A:$A,$A17) -> 4217167410 | AD17: =SUMIFS(전년!BA:BA,전년!$A:$A,$A17) -> 4262820360 | AE17: =IFERROR(T17-Z17,"") -> 379705530 | AF17: =IFERROR(U17-AA17,"") -> -353478896 | AG17: =IFERROR(V17-AB17,"") -> -141191190 | AH17: =IFERROR(W17-AC17,"") -> 367313240 | AI17: =IFERROR(X17-AD17,"") -> 407395810 | AJ17: =IFERROR(T17/Z17-1,"") -> 0.28784072 | AK17: =IFERROR(U17/AA17-1,"") -> -0.068252775 | AL17: =IFERROR(V17/AB17-1,"") -> -0.031121677 | AM17: =IFERROR(W17/AC17-1,"") -> 0.087099516 | AN17: =IFERROR(X17/AD17-1,"") -> 0.095569547 | AP17: 1397469000 | AQ17: =AP17-O17 -> -2769616950 | AU17: =SUM(AU31,AU44,AU11,AU12) -> 0
A18: 리테일채널팀 | C18: =H18/K18-1 -> 0.1807863 | G18: 리테일채널 | H18: =SUM(H34,H38,H47,H51) -> 9661000000 | I18: =SUM(T18,U18,V18,W18,X18) -> 9802184746 | J18: =IFERROR(I18/$H18,"") -> 1.0146139 | K18: =SUMIFS(전년!$BD:$BD,전년!$A:$A,$A18) -> 8181836130 | L18: =IFERROR(I18/K18-1,"") -> 0.19804217 | M18: 10057603273 | N18: =IFERROR(M18-I18,"") -> 255418527 | O18: 2419725453 | P18: =IFERROR(W18-O18,"") -> -255418527 | Q18: =SUM(Q34,Q38,Q47,Q51) -> 7717549293 | R18: =SUM(R34,R38,R47,R51) -> 6363903035 | S18: =IFERROR(Q18/R18-1,"") -> 0.21270693 | T18: =SUM(T34,T38,T47,T51) -> 1217351263 | U18: =SUM(U34,U38,U47,U51) -> 2232042230 | V18: =SUM(V34,V38,V47,V51) -> 2103848874 | W18: =SUM(W34,W38,W47,W51) -> 2164306926 | X18: =SUM(X34,X38,X47,X51) -> 2084635453 | Z18: =SUMIFS(전년!AW:AW,전년!$A:$A,$A18) -> 643419942 | AA18: =SUMIFS(전년!AX:AX,전년!$A:$A,$A18) -> 1979991852 | AB18: =SUMIFS(전년!AY:AY,전년!$A:$A,$A18) -> 1829224711 | AC18: =SUMIFS(전년!AZ:AZ,전년!$A:$A,$A18) -> 2128953262 | AD18: =SUMIFS(전년!BA:BA,전년!$A:$A,$A18) -> 1849244200 | AE18: =IFERROR(T18-Z18,"") -> 573931321 | AF18: =IFERROR(U18-AA18,"") -> 252050378 | AG18: =IFERROR(V18-AB18,"") -> 274624163 | AH18: =IFERROR(W18-AC18,"") -> 35353664 | AI18: =IFERROR(X18-AD18,"") -> 235391253 | AJ18: =IFERROR(T18/Z18-1,"") -> 0.89200114 | AK18: =IFERROR(U18/AA18-1,"") -> 0.12729869 | AL18: =IFERROR(V18/AB18-1,"") -> 0.15013145 | AM18: =IFERROR(W18/AC18-1,"") -> 0.016606125 | AN18: =IFERROR(X18/AD18-1,"") -> 0.12729052 | AP18: 1563971002 | AQ18: =AP18-O18 -> -855754451 | AU18: =SUM(AU34,AU38,AU47,AU51) -> 0
A19: E-biz | C19: =H19/K19-1 -> 0.07426365 | G19: 온라인 | H19: =SUM(H41,H54) -> 3449000000 | I19: =SUM(T19,U19,V19,W19,X19) -> 3686162794 | J19: =IFERROR(I19/$H19,"") -> 1.0687628 | K19: =SUMIFS(전년!$BD:$BD,전년!$A:$A,$A19) -> 3210571259 | L19: =IFERROR(I19/K19-1,"") -> 0.14813299 | M19: 3720180107 | N19: =IFERROR(M19-I19,"") -> 34017313 | O19: 1100000000 | P19: =IFERROR(W19-O19,"") -> -34017313 | Q19: =SUM(Q41,Q54) -> 2656162794 | R19: =SUM(R41,R54) -> 2158980399 | S19: =IFERROR(Q19/R19-1,"") -> 0.23028574 | T19: =T41+T54 -> 164163470 | U19: =U41+U54 -> 665879738 | V19: =V41+V54 -> 760136899 | W19: =W41+W54 -> 1065982687 | X19: =X41+X54 -> 1030000000 | Z19: =SUMIFS(전년!AW:AW,전년!$A:$A,$A19) -> 45397850 | AA19: =SUMIFS(전년!AX:AX,전년!$A:$A,$A19) -> 581126870 | AB19: =SUMIFS(전년!AY:AY,전년!$A:$A,$A19) -> 627035364 | AC19: =SUMIFS(전년!AZ:AZ,전년!$A:$A,$A19) -> 866644796 | AD19: =SUMIFS(전년!BA:BA,전년!$A:$A,$A19) -> 1054719710 | AE19: =IFERROR(T19-Z19,"") -> 118765620 | AF19: =IFERROR(U19-AA19,"") -> 84752868 | AG19: =IFERROR(V19-AB19,"") -> 133101535 | AH19: =IFERROR(W19-AC19,"") -> 199337891 | AI19: =IFERROR(X19-AD19,"") -> -24719710 | AJ19: =IFERROR(T19/Z19-1,"") -> 2.6161067 | AK19: =IFERROR(U19/AA19-1,"") -> 0.14584228 | AL19: =IFERROR(V19/AB19-1,"") -> 0.21227118 | AM19: =IFERROR(W19/AC19-1,"") -> 0.23001106 | AN19: =IFERROR(X19/AD19-1,"") -> -0.023437231 | AP19: 610438352 | AQ19: =AP19-O19 -> -489561648 | AU19: =AU41+AU54 -> 0
P20: =IFERROR(W20-O20,"") -> 0
E21: 유통별 (국내+RF) | G21: SUM | H21: =SUM(H22:H27) -> 33000000000 | I21: =SUM(I22:I27) -> 33662946220 | J21: =IFERROR(I21/$H21,"") -> 1.0200893 | K21: =SUM(K22:K27) -> 31007987365 | L21: =IFERROR(I21/K21-1,"") -> 0.085621773 | M21: 33534987360 | N21: =IFERROR(M21-I21,"") -> -127958860 | O21: 7686811403 | P21: =IFERROR(W21-O21,"") -> 127958860 | Q21: =SUM(Q22:Q27) -> 25901904597 | R21: =SUM(R22:R27) -> 23809938360 | S21: =IFERROR(Q21/R21-1,"") -> 0.087861052 | T21: =SUM(T22:T27) -> 3080371793 | U21: =SUM(U22:U27) -> 7723410468 | V21: =SUM(V22:V27) -> 7259542073 | W21: =SUM(W22:W27) -> 7814770263 | X21: =SUM(X22:X27) -> 7784851623 | Z21: =SUM(Z22:Z27) -> 2007969322 | AA21: =SUM(AA22:AA27) -> 7740086118 | AB21: =SUM(AB22:AB27) -> 6993007565 | AC21: =SUM(AC22:AC27) -> 7212765468 | AD21: =SUM(AD22:AD27) -> 7166784270 | AE21: =IFERROR(T21-Z21,"") -> 1072402471 | AF21: =IFERROR(U21-AA21,"") -> -16675650 | AG21: =IFERROR(V21-AB21,"") -> 266534508 | AH21: =IFERROR(W21-AC21,"") -> 602004795 | AI21: =IFERROR(X21-AD21,"") -> 618067353 | AJ21: =IFERROR(T21/Z21-1,"") -> 0.53407314 | AK21: =IFERROR(U21/AA21-1,"") -> -0.0021544528 | AL21: =IFERROR(V21/AB21-1,"") -> 0.038114432 | AM21: =IFERROR(W21/AC21-1,"") -> 0.083463797 | AN21: =IFERROR(X21/AD21-1,"") -> 0.086240541 | AU21: =SUM(AU22:AU27) -> 0
G22: 백화점 | H22: =SUM(H31,H44) -> 9040000000 | I22: =SUM(I31,I44) -> 9468121580 | J22: =IFERROR(I22/$H22,"") -> 1.0473586 | K22: =SUM(K31,K44) -> 8424280990 | L22: =IFERROR(I22/K22-1,"") -> 0.12390857 | M22: 9167203980 | N22: =IFERROR(M22-I22,"") -> -300917600 | O22: 1710000000 | P22: =IFERROR(W22-O22,"") -> 300917600 | Q22: =SUM(Q31,Q44) -> 6951931580 | R22: =SUM(R31,R44) -> 6583071460 | S22: =IFERROR(Q22/R22-1,"") -> 0.056031614 | T22: =SUM(T31,T44) -> 1027025060 | U22: =SUM(U31,U44) -> 2214911820 | V22: =SUM(V31,V44) -> 1675267100 | W22: =SUM(W31,W44) -> 2010917600 | X22: =SUM(X31,X44) -> 2540000000 | Z22: =SUM(Z31,Z44) -> 629823130 | AA22: =SUM(AA31,AA44) -> 2175929920 | AB22: =SUM(AB31,AB44) -> 1953607060 | AC22: =SUM(AC31,AC44) -> 2025110750 | AD22: =SUM(AD31,AD44) -> 1835858840 | AE22: =IFERROR(T22-Z22,"") -> 397201930 | AF22: =IFERROR(U22-AA22,"") -> 38981900 | AG22: =IFERROR(V22-AB22,"") -> -278339960 | AH22: =IFERROR(W22-AC22,"") -> -14193150 | AI22: =IFERROR(X22-AD22,"") -> 704141160 | AJ22: =IFERROR(T22/Z22-1,"") -> 0.63065631 | AK22: =IFERROR(U22/AA22-1,"") -> 0.017915053 | AL22: =IFERROR(V22/AB22-1,"") -> -0.14247489 | AM22: =IFERROR(W22/AC22-1,"") -> -0.0070085797 | AN22: =IFERROR(X22/AD22-1,"") -> 0.38354864 | AU22: =SUM(AU31,AU44) -> 0
G23: 대리점 | H23: =SUM(H35,H36,H48,H49) -> 5910000000 | I23: =SUM(I35,I36,I48,I49) -> 6131445246 | J23: =IFERROR(I23/$H23,"") -> 1.0374696 | K23: =SUM(K35,K36,K48,K49) -> 5413851820 | L23: =IFERROR(I23/K23-1,"") -> 0.13254767 | M23: 6345818173 | N23: =IFERROR(M23-I23,"") -> 214372927 | O23: 1487834453 | P23: =IFERROR(W23-O23,"") -> -214372927 | Q23: =SUM(Q35,Q36,Q48,Q49) -> 4892610793 | R23: =SUM(R35,R36,R48,R49) -> 4179532840 | S23: =IFERROR(Q23/R23-1,"") -> 0.17061188 | T23: =SUM(T35,T36,T48,T49) -> 818353513 | U23: =SUM(U35,U36,U48,U49) -> 1447608590 | V23: =SUM(V35,V36,V48,V49) -> 1353187164 | W23: =SUM(W35,W36,W48,W49) -> 1273461526 | X23: =SUM(X35,X36,X48,X49) -> 1238834453 | Z23: =SUM(Z35,Z36,Z48,Z49) -> 397125058 | AA23: =SUM(AA35,AA36,AA48,AA49) -> 1320832712 | AB23: =SUM(AB35,AB36,AB48,AB49) -> 1160610011 | AC23: =SUM(AC35,AC36,AC48,AC49) -> 1479131844 | AD23: =SUM(AD35,AD36,AD48,AD49) -> 1261381432 | AE23: =IFERROR(T23-Z23,"") -> 421228455 | AF23: =IFERROR(U23-AA23,"") -> 126775878 | AG23: =IFERROR(V23-AB23,"") -> 192577153 | AH23: =IFERROR(W23-AC23,"") -> -205670318 | AI23: =IFERROR(X23-AD23,"") -> -22546979 | AJ23: =IFERROR(T23/Z23-1,"") -> 1.0606947 | AK23: =IFERROR(U23/AA23-1,"") -> 0.095981782 | AL23: =IFERROR(V23/AB23-1,"") -> 0.16592753 | AM23: =IFERROR(W23/AC23-1,"") -> -0.139048 | AN23: =IFERROR(X23/AD23-1,"") -> -0.01787483 | AU23: =SUM(AU35,AU36,AU48,AU49) -> 0
G24: 직영점 | H24: =SUM(H38,H51) -> 3401000000 | I24: =SUM(I38,I51) -> 3377798500 | J24: =IFERROR(I24/$H24,"") -> 0.99317804 | K24: =SUM(K38,K51) -> 2562172310 | L24: =IFERROR(I24/K24-1,"") -> 0.31833386 | M24: 3421411100 | N24: =IFERROR(M24-I24,"") -> 43612600 | O24: 871891000 | P24: =IFERROR(W24-O24,"") -> -43612600 | Q24: =SUM(Q38,Q51) -> 2586997500 | R24: =SUM(R38,R51) -> 2018770195 | S24: =IFERROR(Q24/R24-1,"") -> 0.28147201 | T24: =SUM(T38,T51) -> 357161750 | U24: =SUM(U38,U51) -> 712129640 | V24: =SUM(V38,V51) -> 689427710 | W24: =SUM(W38,W51) -> 828278400 | X24: =SUM(X38,X51) -> 790801000 | Z24: =SUM(Z38,Z51) -> 212346884 | AA24: =SUM(AA38,AA51) -> 605555140 | AB24: =SUM(AB38,AB51) -> 622318700 | AC24: =SUM(AC38,AC51) -> 606801418 | AD24: =SUM(AD38,AD51) -> 551322768 | AE24: =IFERROR(T24-Z24,"") -> 144814866 | AF24: =IFERROR(U24-AA24,"") -> 106574500 | AG24: =IFERROR(V24-AB24,"") -> 67109010 | AH24: =IFERROR(W24-AC24,"") -> 221476982 | AI24: =IFERROR(X24-AD24,"") -> 239478232 | AJ24: =IFERROR(T24/Z24-1,"") -> 0.68197312 | AK24: =IFERROR(U24/AA24-1,"") -> 0.17599471 | AL24: =IFERROR(V24/AB24-1,"") -> 0.10783705 | AM24: =IFERROR(W24/AC24-1,"") -> 0.36499088 | AN24: =IFERROR(X24/AD24-1,"") -> 0.43437029 | AU24: =SUM(AU38,AU51) -> 0
G25: 면세+도매 | H25: =SUM(H11,H12) -> 10850000000 | I25: =SUM(I11,I12) -> 10706477100 | J25: =IFERROR(I25/$H25,"") -> 0.98677208 | K25: =SUM(K11,K12) -> 11191298986 | L25: =IFERROR(I25/K25-1,"") -> -0.043321324 | M25: 10590000000 | N25: =IFERROR(M25-I25,"") -> -116477100 | O25: 2457085950 | P25: =IFERROR(W25-O25,"") -> 116477100 | Q25: =SUM(Q11,Q12) -> 8576260930 | R25: =SUM(R11,R12) -> 8703983466 | S25: =IFERROR(Q25/R25-1,"") -> -0.014674032 | T25: =SUM(T11,T12) -> 671832000 | U25: =SUM(U11,U12) -> 2610576680 | V25: =SUM(V11,V12) -> 2720289200 | W25: =SUM(W11,W12) -> 2573563050 | X25: =SUM(X11,X12) -> 2130216170 | Z25: =SUM(Z11,Z12) -> 689328400 | AA25: =SUM(AA11,AA12) -> 3003037476 | AB25: =SUM(AB11,AB12) -> 2583140430 | AC25: =SUM(AC11,AC12) -> 2192056660 | AD25: =SUM(AD11,AD12) -> 2426961520 | AE25: =IFERROR(T25-Z25,"") -> -17496400 | AF25: =IFERROR(U25-AA25,"") -> -392460796 | AG25: =IFERROR(V25-AB25,"") -> 137148770 | AH25: =IFERROR(W25-AC25,"") -> 381506390 | AI25: =IFERROR(X25-AD25,"") -> -296745350 | AJ25: =IFERROR(T25/Z25-1,"") -> -0.025381806 | AK25: =IFERROR(U25/AA25-1,"") -> -0.13068794 | AL25: =IFERROR(V25/AB25-1,"") -> 0.053093811 | AM25: =IFERROR(W25/AC25-1,"") -> 0.17404039 | AN25: =IFERROR(X25/AD25-1,"") -> -0.12227032 | AU25: =SUM(AU11,AU12) -> 0
G26: 온라인 | H26: =SUM(H41,H54) -> 3449000000 | I26: =SUM(I41,I54) -> 3686162794 | J26: =IFERROR(I26/$H26,"") -> 1.0687628 | K26: =SUM(K41,K54) -> 3210571259 | L26: =IFERROR(I26/K26-1,"") -> 0.14813299 | M26: 3720180107 | N26: =IFERROR(M26-I26,"") -> 34017313 | O26: 1100000000 | P26: =IFERROR(W26-O26,"") -> -34017313 | Q26: =SUM(Q41,Q54) -> 2656162794 | R26: =SUM(R41,R54) -> 2158980399 | S26: =IFERROR(Q26/R26-1,"") -> 0.23028574 | T26: =SUM(T41,T54) -> 164163470 | U26: =SUM(U41,U54) -> 665879738 | V26: =SUM(V41,V54) -> 760136899 | W26: =SUM(W41,W54) -> 1065982687 | X26: =SUM(X41,X54) -> 1030000000 | Z26: =SUM(Z41,Z54) -> 45397850 | AA26: =SUM(AA41,AA54) -> 581126870 | AB26: =SUM(AB41,AB54) -> 627035364 | AC26: =SUM(AC41,AC54) -> 866644796 | AD26: =SUM(AD41,AD54) -> 1054719710 | AE26: =IFERROR(T26-Z26,"") -> 118765620 | AF26: =IFERROR(U26-AA26,"") -> 84752868 | AG26: =IFERROR(V26-AB26,"") -> 133101535 | AH26: =IFERROR(W26-AC26,"") -> 199337891 | AI26: =IFERROR(X26-AD26,"") -> -24719710 | AJ26: =IFERROR(T26/Z26-1,"") -> 2.6161067 | AK26: =IFERROR(U26/AA26-1,"") -> 0.14584228 | AL26: =IFERROR(V26/AB26-1,"") -> 0.21227118 | AM26: =IFERROR(W26/AC26-1,"") -> 0.23001106 | AN26: =IFERROR(X26/AD26-1,"") -> -0.023437231 | AU26: =SUM(AU41,AU54) -> 0
G27: 상설(위탁) | H27: =SUM(H37,H50) -> 350000000 | I27: =SUM(I37,I50) -> 292941000 | J27: =IFERROR(I27/$H27,"") -> 0.83697429 | K27: =SUM(K37,K50) -> 205812000 | L27: =IFERROR(I27/K27-1,"") -> 0.42334266 | M27: 290374000 | O27: 60000000 | P27: =IFERROR(W27-O27,"") -> 2567000 | Q27: =SUM(Q37,Q50) -> 237941000 | R27: =SUM(R37,R50) -> 165600000 | S27: =IFERROR(Q27/R27-1,"") -> 0.43684179 | T27: =SUM(T37,T50) -> 41836000 | U27: =SUM(U37,U50) -> 72304000 | V27: =SUM(V37,V50) -> 61234000 | W27: =SUM(W37,W50) -> 62567000 | X27: =SUM(X37,X50) -> 55000000 | Z27: =SUM(Z37,Z50) -> 33948000 | AA27: =SUM(AA37,AA50) -> 53604000 | AB27: =SUM(AB37,AB50) -> 46296000 | AC27: =SUM(AC37,AC50) -> 43020000 | AD27: =SUM(AD37,AD50) -> 36540000 | AE27: =IFERROR(T27-Z27,"") -> 7888000 | AF27: =IFERROR(U27-AA27,"") -> 18700000 | AG27: =IFERROR(V27-AB27,"") -> 14938000 | AH27: =IFERROR(W27-AC27,"") -> 19547000 | AI27: =IFERROR(X27-AD27,"") -> 18460000 | AJ27: =IFERROR(T27/Z27-1,"") -> 0.23235537 | AK27: =IFERROR(U27/AA27-1,"") -> 0.34885456 | AL27: =IFERROR(V27/AB27-1,"") -> 0.32266287 | AM27: =IFERROR(W27/AC27-1,"") -> 0.45437006 | AN27: =IFERROR(X27/AD27-1,"") -> 0.50519978 | AU27: =SUM(AU37,AU50) -> 0
P28: =IFERROR(W28-O28,"") -> 0
E29: 국내+RF | P29: =IFERROR(W29-O29,"") -> 0
E30: 순수 | G30: SUM | H30: =SUM(H31,H34,,H41,H38) -> 15876350000 | I30: =SUM(T30,U30,V30,W30,X30) -> 16485909430 | J30: =IFERROR(I30/$H30,"") -> 1.0383942 | K30: =SUM(K31,K34,K38,K41) -> 16064043254 | L30: =IFERROR(I30/K30-1,"") -> 0.026261519 | M30: 16614683058 | N30: =IFERROR(M30-I30,"") -> 128773628 | O30: 4221534453 | P30: =IFERROR(W30-O30,"") -> -128773628 | Q30: =SUM(Q31,Q34,,Q41,Q38) -> 12460184977 | R30: =SUM(R31,R34,,R41,R38) -> 12023022611 | S30: =IFERROR(Q30/R30-1,"") -> 0.036360438 | T30: =SUM(T31,T34,,T41,T38) -> 1493165425 | U30: =SUM(U31,U34,,U41,U38) -> 3362694684 | V30: =SUM(V31,V34,,V41,V38) -> 3487754043 | W30: =SUM(W31,W34,,W41,W38) -> 4092760825 | X30: =SUM(X31,X34,,X41,X38) -> 4049534453 | Z30: =SUM(Z31,Z34,,Z41,Z38) -> 9.5938176e+08 | AA30: =SUM(AA31,AA34,,AA41,AA38) -> 3.1722938e+09 | AB30: =SUM(AB31,AB34,,AB41,AB38) -> 3.0480081e+09 | AC30: =SUM(AC31,AC34,,AC41,AC38) -> 3.6863212e+09 | AD30: =SUM(AD31,AD34,,AD41,AD38) -> 3.7286415e+09 | AE30: =IFERROR(T30-Z30,"") -> 5.3378366e+08 | AF30: =IFERROR(U30-AA30,"") -> 1.9040091e+08 | AG30: =IFERROR(V30-AB30,"") -> 4.397459e+08 | AH30: =IFERROR(W30-AC30,"") -> 4.0643958e+08 | AI30: =IFERROR(X30-AD30,"") -> 3.2089292e+08 | AJ30: =IFERROR(T30/Z30-1,"") -> 0.55638296 | AK30: =IFERROR(U30/AA30-1,"") -> 0.060019949 | AL30: =IFERROR(V30/AB30-1,"") -> 0.1442732 | AM30: =IFERROR(W30/AC30-1,"") -> 0.11025615 | AN30: =IFERROR(X30/AD30-1,"") -> 0.086061618 | AU30: =SUM(AU31,AU34,,AU41,AU38) -> 0
A31: 파트너채널팀 | C31: * | G31: 백화점 | H31: =SUM(H32:H33) -> 5200000000 | I31: =SUM(T31,U31,V31,W31,X31) -> 5131108938 | J31: =IFERROR(I31/$H31,"") -> 0.98675172 | K31: =SUM(K32:K33) -> 6081814767 | L31: =IFERROR(I31/K31-1,"") -> -0.15631943 | M31: 5160022768 | N31: =IFERROR(M31-I31,"") -> 28913830 | O31: 1190000000 | P31: =IFERROR(W31-O31,"") -> -28913830 | Q31: =SUM(Q32:Q33) -> 3914918938 | R31: =SUM(R32:R33) -> 4686626737 | S31: =IFERROR(Q31/R31-1,"") -> -0.16466167 | T31: =SUM(T32:T33) -> 571375582 | U31: =SUM(U32:U33) -> 1052868856 | V31: =SUM(V32:V33)-23810000 -> 1105778330 | W31: =SUM(W32:W33) -> 1161086170 | X31: =SUM(X32:X33) -> 1240000000 | Z31: =SUM(Z32:Z33) -> 3.9962833e+08 | AA31: =SUM(AA32:AA33) -> 1.1643536e+09 | AB31: =SUM(AB32:AB33) -> 1.1103904e+09 | AC31: =SUM(AC32:AC33) -> 1.3191093e+09 | AD31: =SUM(AD32:AD33) -> 1.2465222e+09 | AE31: =IFERROR(T31-Z31,"") -> 1.7174725e+08 | AF31: =IFERROR(U31-AA31,"") -> -1.1148472e+08 | AG31: =IFERROR(V31-AB31,"") -> -4612093.4 | AH31: =IFERROR(W31-AC31,"") -> -1.5802315e+08 | AI31: =IFERROR(X31-AD31,"") -> -6522175.4 | AJ31: =IFERROR(T31/Z31-1,"") -> 0.42976744 | AK31: =IFERROR(U31/AA31-1,"") -> -0.095748168 | AL31: =IFERROR(V31/AB31-1,"") -> -0.0041535781 | AM31: =IFERROR(W31/AC31-1,"") -> -0.11979534 | AN31: =IFERROR(X31/AD31-1,"") -> -0.005232298 | AU31: =SUM(AU32:AU33) -> 0
A32: =A31 -> 파트너채널팀 | B32: 국내 | C32: * | G32: 국내 | H32: 5000000000 | I32: =SUM(T32,U32,V32,W32,X32) -> 4905921638 | J32: =IFERROR(I32/$H32,"") -> 0.98118433 | K32: =SUMIFS('단체(전년마감)'!$AF:$AF,'단체(전년마감)'!$B:$B,요약!$A32,'단체(전년마감)'!$C:$C,요약!$B32,'단체(전년마감)'!$D:$D,요약!$C32) -> 5926623467 | L32: =IFERROR(I32/K32-1,"") -> -0.17222316 | M32: 4970500368 | N32: =IFERROR(M32-I32,"") -> 64578730 | O32: 1150000000 | P32: =IFERROR(W32-O32,"") -> -64578730 | Q32: =SUMIFS('단체(당년)'!$AF:$AF,'단체(당년)'!$B:$B,요약!$A32,'단체(당년)'!$C:$C,요약!$B32,'단체(당년)'!$D:$D,요약!$C32) -> 3705921638 | R32: =SUMIFS('단체(전년-동일자)'!$AF:$AF,'단체(전년-동일자)'!$B:$B,요약!$A32,'단체(전년-동일자)'!$C:$C,요약!$B32,'단체(전년-동일자)'!$D:$D,요약!$C32) -> 4568233837 | S32: =IFERROR(Q32/R32-1,"") -> -0.18876271 | T32: =SUMIFS('단체(당년)'!$AF:$AF,'단체(당년)'!$B:$B,$A32,'단체(당년)'!$C:$C,$B32,'단체(당년)'!$D:$D,$C32,'단체(당년)'!$A:$A,T$1) -> 545556982 | U32: =SUMIFS('단체(당년)'!$AF:$AF,'단체(당년)'!$B:$B,$A32,'단체(당년)'!$C:$C,$B32,'단체(당년)'!$D:$D,$C32,'단체(당년)'!$A:$A,U$1) -> 1000331756 | V32: =SUMIFS('단체(당년)'!$AF:$AF,'단체(당년)'!$B:$B,$A32,'단체(당년)'!$C:$C,$B32,'단체(당년)'!$D:$D,$C32,'단체(당년)'!$A:$A,V$1) -> 1074611630 | W32: =SUMIFS('단체(당년)'!$AF:$AF,'단체(당년)'!$B:$B,$A32,'단체(당년)'!$C:$C,$B32,'단체(당년)'!$D:$D,$C32,'단체(당년)'!$A:$A,W$1) -> 1085421270 | X32: 1200000000 | Z32: 3.8944943e+08 | AA32: 1.1266989e+09 | AB32: 1.0712945e+09 | AC32: 1.2837034e+09 | AD32: 1.2118698e+09 | AE32: =IFERROR(T32-Z32,"") -> 1.5610755e+08 | AF32: =IFERROR(U32-AA32,"") -> -1.2636712e+08 | AG32: =IFERROR(V32-AB32,"") -> 3317106.6 | AH32: =IFERROR(W32-AC32,"") -> -1.9828215e+08 | AI32: =IFERROR(X32-AD32,"") -> -11869775 | AJ32: =IFERROR(T32/Z32-1,"") -> 0.40084163 | AK32: =IFERROR(U32/AA32-1,"") -> -0.11215696 | AL32: =IFERROR(V32/AB32-1,"") -> 0.0030963536 | AM32: =IFERROR(W32/AC32-1,"") -> -0.15446103 | AN32: =IFERROR(X32/AD32-1,"") -> -0.0097945965 | AU32: =SUMIFS('단체(당년)'!$AF:$AF,'단체(당년)'!$B:$B,$A32,'단체(당년)'!$C:$C,$B32,'단체(당년)'!$D:$D,$C32,'단체(당년)'!$A:$A,AU$1) -> 0
A33: =A32 -> 파트너채널팀 | B33: RF | C33: * | G33: RF | H33: 200000000 | I33: =SUM(T33,U33,V33,W33,X33) -> 248997300 | J33: =IFERROR(I33/$H33,"") -> 1.2449865 | K33: =SUMIFS('RF(전년)'!$BG:$BG,'RF(전년)'!$B:$B,요약!$A33,'RF(전년)'!$D:$D,요약!$E$30,'RF(전년)'!$C:$C,요약!$C33) -> 155191300 | L33: =IFERROR(I33/K33-1,"") -> 0.60445399 | M33: 213332400 | N33: =IFERROR(M33-I33,"") -> -35664900 | O33: 40000000 | P33: =IFERROR(W33-O33,"") -> 35664900 | Q33: =SUMIFS('RF(당년)'!$BF:$BF,'RF(당년)'!$B:$B,요약!$A33,'RF(당년)'!$C:$C,요약!$C33,'RF(당년)'!$D:$D,요약!$E$30) -> 208997300 | R33: =SUMIFS('RF(전년)'!$BF:$BF,'RF(전년)'!$B:$B,요약!$A33,'RF(전년)'!$C:$C,요약!$C33,'RF(전년)'!$D:$D,요약!$E$30) -> 118392900 | S33: =IFERROR(Q33/R33-1,"") -> 0.76528576 | T33: =SUMIFS('RF(당년)'!AZ:AZ,'RF(당년)'!$B:$B,요약!$A33,'RF(당년)'!$C:$C,요약!$C33,'RF(당년)'!$D:$D,요약!$E$30) -> 25818600 | U33: =SUMIFS('RF(당년)'!BA:BA,'RF(당년)'!$B:$B,요약!$A33,'RF(당년)'!$C:$C,요약!$C33,'RF(당년)'!$D:$D,요약!$E$30) -> 52537100 | V33: =SUMIFS('RF(당년)'!BB:BB,'RF(당년)'!$B:$B,요약!$A33,'RF(당년)'!$C:$C,요약!$C33,'RF(당년)'!$D:$D,요약!$E$30) -> 54976700 | W33: =SUMIFS('RF(당년)'!BC:BC,'RF(당년)'!$B:$B,요약!$A33,'RF(당년)'!$C:$C,요약!$C33,'RF(당년)'!$D:$D,요약!$E$30) -> 75664900 | X33: 40000000 | Z33: =SUMIFS('RF(전년)'!AZ:AZ,'RF(전년)'!$B:$B,요약!$A33,'RF(전년)'!$C:$C,요약!$C33,'RF(전년)'!$D:$D,요약!$E$30) -> 10178900 | AA33: =SUMIFS('RF(전년)'!BA:BA,'RF(전년)'!$B:$B,요약!$A33,'RF(전년)'!$C:$C,요약!$C33,'RF(전년)'!$D:$D,요약!$E$30) -> 37654700 | AB33: =SUMIFS('RF(전년)'!BB:BB,'RF(전년)'!$B:$B,요약!$A33,'RF(전년)'!$C:$C,요약!$C33,'RF(전년)'!$D:$D,요약!$E$30) -> 39095900 | AC33: =SUMIFS('RF(전년)'!BC:BC,'RF(전년)'!$B:$B,요약!$A33,'RF(전년)'!$C:$C,요약!$C33,'RF(전년)'!$D:$D,요약!$E$30) -> 35405900 | AD33: =SUMIFS('RF(전년)'!BD:BD,'RF(전년)'!$B:$B,요약!$A33,'RF(전년)'!$C:$C,요약!$C33,'RF(전년)'!$D:$D,요약!$E$30) -> 34652400 | AE33: =IFERROR(T33-Z33,"") -> 15639700 | AF33: =IFERROR(U33-AA33,"") -> 14882400 | AG33: =IFERROR(V33-AB33,"") -> 15880800 | AH33: =IFERROR(W33-AC33,"") -> 40259000 | AI33: =IFERROR(X33-AD33,"") -> 5347600 | AJ33: =IFERROR(T33/Z33-1,"") -> 1.5364823 | AK33: =IFERROR(U33/AA33-1,"") -> 0.39523353 | AL33: =IFERROR(V33/AB33-1,"") -> 0.40620116 | AM33: =IFERROR(W33/AC33-1,"") -> 1.1370704 | AN33: =IFERROR(X33/AD33-1,"") -> 0.1543212 | AU33: =SUMIFS('RF(당년)'!CA:CA,'RF(당년)'!$B:$B,요약!$A33,'RF(당년)'!$C:$C,요약!$C33,'RF(당년)'!$D:$D,요약!$E$30) -> 0
A34: 리테일채널팀 | C34: 대리점 | G34: 대리점 | H34: =SUM(H35:H37) -> 4200000000 | I34: =SUM(T34,U34,V34,W34,X34) -> 4547248698 | J34: =IFERROR(I34/$H34,"") -> 1.0826783 | K34: =SUM(K35:K37) -> 4553466318 | L34: =IFERROR(I34/K34-1,"") -> -0.0013654696 | M34: 4716069583 | N34: =IFERROR(M34-I34,"") -> 168820885 | O34: 1206234453 | P34: =IFERROR(W34-O34,"") -> -168820885 | Q34: =SUM(Q35:Q37) -> 3431014245 | R34: =SUM(R35:R37) -> 3452503880 | S34: =IFERROR(Q34/R34-1,"") -> -0.0062243623 | T34: =SUM(T35:T37) -> 477745673 | U34: =SUM(U35:U37) -> 957916790 | V34: =SUM(V35:V37) -> 957938214 | W34: =SUM(W35:W37) -> 1037413568 | X34: =SUM(X35:X37) -> 1116234453 | Z34: =SUM(Z35:Z37) -> 3.0200869e+08 | AA34: =SUM(AA35:AA37) -> 9.0278579e+08 | AB34: =SUM(AB35:AB37) -> 8.2525295e+08 | AC34: =SUM(AC35:AC37) -> 9.6257922e+08 | AD34: =SUM(AD35:AD37) -> 9.3267888e+08 | AE34: =IFERROR(T34-Z34,"") -> 1.7573698e+08 | AF34: =IFERROR(U34-AA34,"") -> 55131003 | AG34: =IFERROR(V34-AB34,"") -> 1.3268526e+08 | AH34: =IFERROR(W34-AC34,"") -> 74834352 | AI34: =IFERROR(X34-AD34,"") -> 1.8355557e+08 | AJ34: =IFERROR(T34/Z34-1,"") -> 0.58189378 | AK34: =IFERROR(U34/AA34-1,"") -> 0.061067646 | AL34: =IFERROR(V34/AB34-1,"") -> 0.16078132 | AM34: =IFERROR(W34/AC34-1,"") -> 0.077743578 | AN34: =IFERROR(X34/AD34-1,"") -> 0.19680469 | AU34: =SUM(AU35:AU37) -> 0
A35: =A34 -> 리테일채널팀 | B35: 국내 | C35: 대리점 | G35: 국내 | H35: 3600000000 | I35: =SUM(T35,U35,V35,W35,X35) -> 3974684838 | J35: =IFERROR(I35/$H35,"") -> 1.1040791 | K35: =SUMIFS('단체(전년마감)'!$AF:$AF,'단체(전년마감)'!$B:$B,요약!$A35,'단체(전년마감)'!$C:$C,요약!$B35,'단체(전년마감)'!$D:$D,요약!$C35) -> 4175519018 | L35: =IFERROR(I35/K35-1,"") -> -0.048098016 | M35: 4141311170 | N35: =IFERROR(M35-I35,"") -> 166626332 | O35: 1085000000 | P35: =IFERROR(W35-O35,"") -> -166626332 | Q35: =SUMIFS('단체(당년)'!$AF:$AF,'단체(당년)'!$B:$B,요약!$A35,'단체(당년)'!$C:$C,요약!$B35,'단체(당년)'!$D:$D,요약!$C35) -> 2974684838 | R35: =SUMIFS('단체(전년-동일자)'!$AF:$AF,'단체(전년-동일자)'!$B:$B,요약!$A35,'단체(전년-동일자)'!$C:$C,요약!$B35,'단체(전년-동일자)'!$D:$D,요약!$C35) -> 3156316380 | S35: =IFERROR(Q35/R35-1,"") -> -0.057545417 | T35: =SUMIFS('단체(당년)'!$AF:$AF,'단체(당년)'!$B:$B,$A35,'단체(당년)'!$C:$C,$B35,'단체(당년)'!$D:$D,$C35,'단체(당년)'!$A:$A,T$1) -> 419630566 | U35: =SUMIFS('단체(당년)'!$AF:$AF,'단체(당년)'!$B:$B,$A35,'단체(당년)'!$C:$C,$B35,'단체(당년)'!$D:$D,$C35,'단체(당년)'!$A:$A,U$1) -> 817240790 | V35: =SUMIFS('단체(당년)'!$AF:$AF,'단체(당년)'!$B:$B,$A35,'단체(당년)'!$C:$C,$B35,'단체(당년)'!$D:$D,$C35,'단체(당년)'!$A:$A,V$1) -> 819439814 | W35: =SUMIFS('단체(당년)'!$AF:$AF,'단체(당년)'!$B:$B,$A35,'단체(당년)'!$C:$C,$B35,'단체(당년)'!$D:$D,$C35,'단체(당년)'!$A:$A,W$1) -> 918373668 | X35: 1000000000 | Z35: 2.5232239e+08 | AA35: 8.0798049e+08 | AB35: 7.4173495e+08 | AC35: 8.8005042e+08 | AD35: 8.5426698e+08 | AE35: =IFERROR(T35-Z35,"") -> 1.6730817e+08 | AF35: =IFERROR(U35-AA35,"") -> 9260303.2 | AG35: =IFERROR(V35-AB35,"") -> 77704861 | AH35: =IFERROR(W35-AC35,"") -> 38323252 | AI35: =IFERROR(X35-AD35,"") -> 1.4573302e+08 | AJ35: =IFERROR(T35/Z35-1,"") -> 0.66307302 | AK35: =IFERROR(U35/AA35-1,"") -> 0.011461048 | AL35: =IFERROR(V35/AB35-1,"") -> 0.10476095 | AM35: =IFERROR(W35/AC35-1,"") -> 0.043546656 | AN35: =IFERROR(X35/AD35-1,"") -> 0.17059424 | AU35: =SUMIFS('단체(당년)'!$AF:$AF,'단체(당년)'!$B:$B,$A35,'단체(당년)'!$C:$C,$B35,'단체(당년)'!$D:$D,$C35,'단체(당년)'!$A:$A,AU$1) -> 0
A36: =A35 -> 리테일채널팀 | B36: RF | C36: 대리점 | G36: RF | H36: 250000000 | I36: =SUM(T36,U36,V36,W36,X36) -> 279622860 | J36: =IFERROR(I36/$H36,"") -> 1.1184914 | K36: =SUMIFS('RF(전년)'!$BG:$BG,'RF(전년)'!$B:$B,요약!$A36,'RF(전년)'!$D:$D,요약!$E$30,'RF(전년)'!$C:$C,요약!$C36) -> 172135300 | L36: =IFERROR(I36/K36-1,"") -> 0.62443648 | M36: 2.8438441e+08 | N36: =IFERROR(M36-I36,"") -> 4761553 | O36: 61234453 | P36: =IFERROR(W36-O36,"") -> -4761553 | Q36: =SUMIFS('RF(당년)'!$BF:$BF,'RF(당년)'!$B:$B,요약!$A36,'RF(당년)'!$C:$C,요약!$C36,'RF(당년)'!$D:$D,요약!$E$30) -> 218388407 | R36: =SUMIFS('RF(전년)'!$BF:$BF,'RF(전년)'!$B:$B,요약!$A36,'RF(전년)'!$C:$C,요약!$C36,'RF(전년)'!$D:$D,요약!$E$30) -> 130587500 | S36: =IFERROR(Q36/R36-1,"") -> 0.67235307 | T36: =SUMIFS('RF(당년)'!AZ:AZ,'RF(당년)'!$B:$B,요약!$A36,'RF(당년)'!$C:$C,요약!$C36,'RF(당년)'!$D:$D,요약!$E$30) -> 16279107 | U36: =SUMIFS('RF(당년)'!BA:BA,'RF(당년)'!$B:$B,요약!$A36,'RF(당년)'!$C:$C,요약!$C36,'RF(당년)'!$D:$D,요약!$E$30) -> 68372000 | V36: =SUMIFS('RF(당년)'!BB:BB,'RF(당년)'!$B:$B,요약!$A36,'RF(당년)'!$C:$C,요약!$C36,'RF(당년)'!$D:$D,요약!$E$30) -> 77264400 | W36: =SUMIFS('RF(당년)'!BC:BC,'RF(당년)'!$B:$B,요약!$A36,'RF(당년)'!$C:$C,요약!$C36,'RF(당년)'!$D:$D,요약!$E$30) -> 56472900 | X36: 61234453 | Z36: =SUMIFS('RF(전년)'!AZ:AZ,'RF(전년)'!$B:$B,요약!$A36,'RF(전년)'!$C:$C,요약!$C36,'RF(전년)'!$D:$D,요약!$E$30) -> 15738300 | AA36: =SUMIFS('RF(전년)'!BA:BA,'RF(전년)'!$B:$B,요약!$A36,'RF(전년)'!$C:$C,요약!$C36,'RF(전년)'!$D:$D,요약!$E$30) -> 41201300 | AB36: =SUMIFS('RF(전년)'!BB:BB,'RF(전년)'!$B:$B,요약!$A36,'RF(전년)'!$C:$C,요약!$C36,'RF(전년)'!$D:$D,요약!$E$30) -> 37222000 | AC36: =SUMIFS('RF(전년)'!BC:BC,'RF(전년)'!$B:$B,요약!$A36,'RF(전년)'!$C:$C,요약!$C36,'RF(전년)'!$D:$D,요약!$E$30) -> 39508800 | AD36: =SUMIFS('RF(전년)'!BD:BD,'RF(전년)'!$B:$B,요약!$A36,'RF(전년)'!$C:$C,요약!$C36,'RF(전년)'!$D:$D,요약!$E$30) -> 41871900 | AE36: =IFERROR(T36-Z36,"") -> 540807 | AF36: =IFERROR(U36-AA36,"") -> 27170700 | AG36: =IFERROR(V36-AB36,"") -> 40042400 | AH36: =IFERROR(W36-AC36,"") -> 16964100 | AI36: =IFERROR(X36-AD36,"") -> 19362553 | AJ36: =IFERROR(T36/Z36-1,"") -> 0.034362479 | AK36: =IFERROR(U36/AA36-1,"") -> 0.6594622 | AL36: =IFERROR(V36/AB36-1,"") -> 1.0757724 | AM36: =IFERROR(W36/AC36-1,"") -> 0.42937523 | AN36: =IFERROR(X36/AD36-1,"") -> 0.46242356 | AU36: =SUMIFS('RF(당년)'!CA:CA,'RF(당년)'!$B:$B,요약!$A36,'RF(당년)'!$C:$C,요약!$C36,'RF(당년)'!$D:$D,요약!$E$30) -> 0
A37: =A36 -> 리테일채널팀 | B37: 국내 | C37: 상설(위탁) | G37: 상설(위탁) | H37: 350000000 | I37: =SUM(T37,U37,V37,W37,X37) -> 292941000 | J37: =IFERROR(I37/$H37,"") -> 0.83697429 | K37: =SUMIFS('단체(전년마감)'!$AF:$AF,'단체(전년마감)'!$B:$B,요약!$A37,'단체(전년마감)'!$C:$C,요약!$B37,'단체(전년마감)'!$D:$D,요약!$C37) -> 205812000 | L37: =IFERROR(I37/K37-1,"") -> 0.42334266 | M37: 290374000 | O37: 60000000 | P37: =IFERROR(W37-O37,"") -> 2567000 | Q37: =SUMIFS('단체(당년)'!$AF:$AF,'단체(당년)'!$B:$B,요약!$A37,'단체(당년)'!$C:$C,요약!$B37,'단체(당년)'!$D:$D,요약!$C37) -> 237941000 | R37: =SUMIFS('단체(전년-동일자)'!$AF:$AF,'단체(전년-동일자)'!$B:$B,요약!$A37,'단체(전년-동일자)'!$C:$C,요약!$B37,'단체(전년-동일자)'!$D:$D,요약!$C37) -> 165600000 | S37: =IFERROR(Q37/R37-1,"") -> 0.43684179 | T37: =SUMIFS('단체(당년)'!$AF:$AF,'단체(당년)'!$B:$B,$A37,'단체(당년)'!$C:$C,$B37,'단체(당년)'!$D:$D,$C37,'단체(당년)'!$A:$A,T$1) -> 41836000 | U37: =SUMIFS('단체(당년)'!$AF:$AF,'단체(당년)'!$B:$B,$A37,'단체(당년)'!$C:$C,$B37,'단체(당년)'!$D:$D,$C37,'단체(당년)'!$A:$A,U$1) -> 72304000 | V37: =SUMIFS('단체(당년)'!$AF:$AF,'단체(당년)'!$B:$B,$A37,'단체(당년)'!$C:$C,$B37,'단체(당년)'!$D:$D,$C37,'단체(당년)'!$A:$A,V$1) -> 61234000 | W37: =SUMIFS('단체(당년)'!$AF:$AF,'단체(당년)'!$B:$B,$A37,'단체(당년)'!$C:$C,$B37,'단체(당년)'!$D:$D,$C37,'단체(당년)'!$A:$A,W$1) -> 62567000 | X37: 55000000 | Z37: =SUMIFS('단체(전년)'!$AF:$AF,'단체(전년)'!$B:$B,$A37,'단체(전년)'!$C:$C,$B37,'단체(전년)'!$D:$D,$C37,'단체(전년)'!$A:$A,T$1) -> 33948000 | AA37: =SUMIFS('단체(전년)'!$AF:$AF,'단체(전년)'!$B:$B,$A37,'단체(전년)'!$C:$C,$B37,'단체(전년)'!$D:$D,$C37,'단체(전년)'!$A:$A,U$1) -> 53604000 | AB37: =SUMIFS('단체(전년)'!$AF:$AF,'단체(전년)'!$B:$B,$A37,'단체(전년)'!$C:$C,$B37,'단체(전년)'!$D:$D,$C37,'단체(전년)'!$A:$A,V$1) -> 46296000 | AC37: =SUMIFS('단체(전년)'!$AF:$AF,'단체(전년)'!$B:$B,$A37,'단체(전년)'!$C:$C,$B37,'단체(전년)'!$D:$D,$C37,'단체(전년)'!$A:$A,W$1) -> 43020000 | AD37: =SUMIFS('단체(전년)'!$AF:$AF,'단체(전년)'!$B:$B,$A37,'단체(전년)'!$C:$C,$B37,'단체(전년)'!$D:$D,$C37,'단체(전년)'!$A:$A,X$1) -> 36540000 | AE37: =IFERROR(T37-Z37,"") -> 7888000 | AF37: =IFERROR(U37-AA37,"") -> 18700000 | AG37: =IFERROR(V37-AB37,"") -> 14938000 | AH37: =IFERROR(W37-AC37,"") -> 19547000 | AI37: =IFERROR(X37-AD37,"") -> 18460000 | AJ37: =IFERROR(T37/Z37-1,"") -> 0.23235537 | AK37: =IFERROR(U37/AA37-1,"") -> 0.34885456 | AL37: =IFERROR(V37/AB37-1,"") -> 0.32266287 | AM37: =IFERROR(W37/AC37-1,"") -> 0.45437006 | AN37: =IFERROR(X37/AD37-1,"") -> 0.50519978 | AU37: =SUMIFS('단체(당년)'!$AF:$AF,'단체(당년)'!$B:$B,$A37,'단체(당년)'!$C:$C,$B37,'단체(당년)'!$D:$D,$C37,'단체(당년)'!$A:$A,AU$1) -> 0
A38: 리테일채널팀 | C38: 직영점 | G38: 직영점 | H38: =SUM(H39:H40) -> 3027350000 | I38: =SUM(T38,U38,V38,W38,X38) -> 3121389000 | J38: =IFERROR(I38/$H38,"") -> 1.0310631 | K38: =SUM(K39:K40) -> 2218190910 | L38: =IFERROR(I38/K38-1,"") -> 0.4071778 | M38: 3018410600 | N38: =IFERROR(M38-I38,"") -> -102978400 | O38: 725300000 | P38: =IFERROR(W38-O38,"") -> 102978400 | Q38: =SUM(Q39:Q40) -> 2458089000 | R38: =SUM(R39:R40) -> 1724911595 | S38: =IFERROR(Q38/R38-1,"") -> 0.42505216 | T38: =SUM(T39:T40) -> 279880700 | U38: =SUM(U39:U40) -> 686029300 | V38: =SUM(V39:V40) -> 663900600 | W38: =SUM(W39:W40) -> 828278400 | X38: =SUM(X39:X40) -> 663300000 | Z38: =SUM(Z39:Z40) -> 212346884 | AA38: =SUM(AA39:AA40) -> 524027540 | AB38: =SUM(AB39:AB40) -> 485329400 | AC38: =SUM(AC39:AC40) -> 537987918 | AD38: =SUM(AD39:AD40) -> 494720768 | AE38: =IFERROR(T38-Z38,"") -> 67533816 | AF38: =IFERROR(U38-AA38,"") -> 162001760 | AG38: =IFERROR(V38-AB38,"") -> 178571200 | AH38: =IFERROR(W38-AC38,"") -> 290290482 | AI38: =IFERROR(X38-AD38,"") -> 168579232 | AJ38: =IFERROR(T38/Z38-1,"") -> 0.31803535 | AK38: =IFERROR(U38/AA38-1,"") -> 0.30914742 | AL38: =IFERROR(V38/AB38-1,"") -> 0.36793815 | AM38: =IFERROR(W38/AC38-1,"") -> 0.5395855 | AN38: =IFERROR(X38/AD38-1,"") -> 0.34075633 | AU38: =SUM(AU39:AU40) -> 0
A39: =A38 -> 리테일채널팀 | B39: 국내 | C39: 직영점 | G39: 국내 | H39: 910000000 | I39: =SUM(T39,U39,V39,W39,X39) -> 912758800 | J39: =IFERROR(I39/$H39,"") -> 1.0030316 | K39: =SUMIFS('단체(전년마감)'!$AF:$AF,'단체(전년마감)'!$B:$B,요약!$A39,'단체(전년마감)'!$C:$C,요약!$B39,'단체(전년마감)'!$D:$D,요약!$C39) -> 968881910 | L39: =IFERROR(I39/K39-1,"") -> -0.057925645 | M39: 907511900 | N39: =IFERROR(M39-I39,"") -> -5246900 | O39: 237300000 | P39: =IFERROR(W39-O39,"") -> 5246900 | Q39: =SUMIFS('단체(당년)'!$AF:$AF,'단체(당년)'!$B:$B,요약!$A39,'단체(당년)'!$C:$C,요약!$B39,'단체(당년)'!$D:$D,요약!$C39) -> 704458800 | R39: =SUMIFS('단체(전년-동일자)'!$AF:$AF,'단체(전년-동일자)'!$B:$B,요약!$A39,'단체(전년-동일자)'!$C:$C,요약!$B39,'단체(전년-동일자)'!$D:$D,요약!$C39) -> 745504195 | S39: =IFERROR(Q39/R39-1,"") -> -0.055057229 | T39: =SUMIFS('단체(당년)'!$AF:$AF,'단체(당년)'!$B:$B,$A39,'단체(당년)'!$C:$C,$B39,'단체(당년)'!$D:$D,$C39,'단체(당년)'!$A:$A,T$1) -> 97123900 | U39: =SUMIFS('단체(당년)'!$AF:$AF,'단체(당년)'!$B:$B,$A39,'단체(당년)'!$C:$C,$B39,'단체(당년)'!$D:$D,$C39,'단체(당년)'!$A:$A,U$1) -> 197467500 | V39: =SUMIFS('단체(당년)'!$AF:$AF,'단체(당년)'!$B:$B,$A39,'단체(당년)'!$C:$C,$B39,'단체(당년)'!$D:$D,$C39,'단체(당년)'!$A:$A,V$1) -> 167320500 | W39: =SUMIFS('단체(당년)'!$AF:$AF,'단체(당년)'!$B:$B,$A39,'단체(당년)'!$C:$C,$B39,'단체(당년)'!$D:$D,$C39,'단체(당년)'!$A:$A,W$1) -> 242546900 | X39: 208300000 | Z39: =SUMIFS('단체(전년)'!$AF:$AF,'단체(전년)'!$B:$B,$A39,'단체(전년)'!$C:$C,$B39,'단체(전년)'!$D:$D,$C39,'단체(전년)'!$A:$A,T$1) -> 89886984 | AA39: =SUMIFS('단체(전년)'!$AF:$AF,'단체(전년)'!$B:$B,$A39,'단체(전년)'!$C:$C,$B39,'단체(전년)'!$D:$D,$C39,'단체(전년)'!$A:$A,U$1) -> 229991640 | AB39: =SUMIFS('단체(전년)'!$AF:$AF,'단체(전년)'!$B:$B,$A39,'단체(전년)'!$C:$C,$B39,'단체(전년)'!$D:$D,$C39,'단체(전년)'!$A:$A,V$1) -> 199416000 | AC39: =SUMIFS('단체(전년)'!$AF:$AF,'단체(전년)'!$B:$B,$A39,'단체(전년)'!$C:$C,$B39,'단체(전년)'!$D:$D,$C39,'단체(전년)'!$A:$A,W$1) -> 260709918 | AD39: =SUMIFS('단체(전년)'!$AF:$AF,'단체(전년)'!$B:$B,$A39,'단체(전년)'!$C:$C,$B39,'단체(전년)'!$D:$D,$C39,'단체(전년)'!$A:$A,X$1) -> 225219068 | AE39: =IFERROR(T39-Z39,"") -> 7236916 | AF39: =IFERROR(U39-AA39,"") -> -32524140 | AG39: =IFERROR(V39-AB39,"") -> -32095500 | AH39: =IFERROR(W39-AC39,"") -> -18163018 | AI39: =IFERROR(X39-AD39,"") -> -16919068 | AJ39: =IFERROR(T39/Z39-1,"") -> 0.080511278 | AK39: =IFERROR(U39/AA39-1,"") -> -0.14141444 | AL39: =IFERROR(V39/AB39-1,"") -> -0.16094747 | AM39: =IFERROR(W39/AC39-1,"") -> -0.069667538 | AN39: =IFERROR(X39/AD39-1,"") -> -0.075122716 | AU39: =SUMIFS('단체(당년)'!$AF:$AF,'단체(당년)'!$B:$B,$A39,'단체(당년)'!$C:$C,$B39,'단체(당년)'!$D:$D,$C39,'단체(당년)'!$A:$A,AU$1) -> 0
A40: =A39 -> 리테일채널팀 | B40: RF | C40: 직영점 | G40: RF | H40: 2117350000 | I40: =SUM(T40,U40,V40,W40,X40) -> 2208630200 | J40: =IFERROR(I40/$H40,"") -> 1.0431106 | K40: =SUMIFS('RF(전년)'!$BG:$BG,'RF(전년)'!$B:$B,요약!$A40,'RF(전년)'!$D:$D,요약!$E$30,'RF(전년)'!$C:$C,요약!$C40) -> 1249309000 | L40: =IFERROR(I40/K40-1,"") -> 0.76788144 | M40: 2110898700 | N40: =IFERROR(M40-I40,"") -> -97731500 | O40: 488000000 | P40: =IFERROR(W40-O40,"") -> 97731500 | Q40: =SUMIFS('RF(당년)'!$BF:$BF,'RF(당년)'!$B:$B,요약!$A40,'RF(당년)'!$C:$C,요약!$C40,'RF(당년)'!$D:$D,요약!$E$30) -> 1753630200 | R40: =SUMIFS('RF(전년)'!$BF:$BF,'RF(전년)'!$B:$B,요약!$A40,'RF(전년)'!$C:$C,요약!$C40,'RF(전년)'!$D:$D,요약!$E$30) -> 979407400 | S40: =IFERROR(Q40/R40-1,"") -> 0.79050128 | T40: =SUMIFS('RF(당년)'!AZ:AZ,'RF(당년)'!$B:$B,요약!$A40,'RF(당년)'!$C:$C,요약!$C40,'RF(당년)'!$D:$D,요약!$E$30) -> 182756800 | U40: =SUMIFS('RF(당년)'!BA:BA,'RF(당년)'!$B:$B,요약!$A40,'RF(당년)'!$C:$C,요약!$C40,'RF(당년)'!$D:$D,요약!$E$30) -> 488561800 | V40: =SUMIFS('RF(당년)'!BB:BB,'RF(당년)'!$B:$B,요약!$A40,'RF(당년)'!$C:$C,요약!$C40,'RF(당년)'!$D:$D,요약!$E$30) -> 496580100 | W40: =SUMIFS('RF(당년)'!BC:BC,'RF(당년)'!$B:$B,요약!$A40,'RF(당년)'!$C:$C,요약!$C40,'RF(당년)'!$D:$D,요약!$E$30) -> 585731500 | X40: 455000000 | Z40: =SUMIFS('RF(전년)'!AZ:AZ,'RF(전년)'!$B:$B,요약!$A40,'RF(전년)'!$C:$C,요약!$C40,'RF(전년)'!$D:$D,요약!$E$30) -> 122459900 | AA40: =SUMIFS('RF(전년)'!BA:BA,'RF(전년)'!$B:$B,요약!$A40,'RF(전년)'!$C:$C,요약!$C40,'RF(전년)'!$D:$D,요약!$E$30) -> 294035900 | AB40: =SUMIFS('RF(전년)'!BB:BB,'RF(전년)'!$B:$B,요약!$A40,'RF(전년)'!$C:$C,요약!$C40,'RF(전년)'!$D:$D,요약!$E$30) -> 285913400 | AC40: =SUMIFS('RF(전년)'!BC:BC,'RF(전년)'!$B:$B,요약!$A40,'RF(전년)'!$C:$C,요약!$C40,'RF(전년)'!$D:$D,요약!$E$30) -> 277278000 | AD40: =SUMIFS('RF(전년)'!BD:BD,'RF(전년)'!$B:$B,요약!$A40,'RF(전년)'!$C:$C,요약!$C40,'RF(전년)'!$D:$D,요약!$E$30) -> 269501700 | AE40: =IFERROR(T40-Z40,"") -> 60296900 | AF40: =IFERROR(U40-AA40,"") -> 194525900 | AG40: =IFERROR(V40-AB40,"") -> 210666700 | AH40: =IFERROR(W40-AC40,"") -> 308453500 | AI40: =IFERROR(X40-AD40,"") -> 185498300 | AJ40: =IFERROR(T40/Z40-1,"") -> 0.49238077 | AK40: =IFERROR(U40/AA40-1,"") -> 0.66157194 | AL40: =IFERROR(V40/AB40-1,"") -> 0.73681996 | AM40: =IFERROR(W40/AC40-1,"") -> 1.1124341 | AN40: =IFERROR(X40/AD40-1,"") -> 0.68830104 | AU40: =SUMIFS('RF(당년)'!CA:CA,'RF(당년)'!$B:$B,요약!$A40,'RF(당년)'!$C:$C,요약!$C40,'RF(당년)'!$D:$D,요약!$E$30) -> 0
...

Sheet 일자별
E1: 파트너채널팀 | F1: =E1 -> 파트너채널팀 | G1: =F1 -> 파트너채널팀 | H1: =G1 -> 파트너채널팀 | I1: =H1 -> 파트너채널팀 | J1: 리테일채널팀 | K1: =J1 -> 리테일채널팀 | L1: =K1 -> 리테일채널팀 | M1: =L1 -> 리테일채널팀 | N1: =M1 -> 리테일채널팀 | O1: E-biz | P1: =O1 -> E-biz | Q1: =P1 -> E-biz | R1: =Q1 -> E-biz | S1: =R1 -> E-biz | Z1: 파트너채널팀 | AA1: =Z1 -> 파트너채널팀 | AB1: =AA1 -> 파트너채널팀 | AC1: =AB1 -> 파트너채널팀 | AD1: =AC1 -> 파트너채널팀
G2: 국내 | H2: 국내 | L2: 국내 | M2: 국내 | AB2: 면세 | AC2: 면세
G3: RF | H3: RF | L3: RF | M3: RF | AB3: 도매 | AC3: 도매
E5: 파트너채널팀(백화점) | J5: 리테일채널팀 | O5: 온라인 | T5: 국내+RF | Z5: 면세+도매 | AF5: MLB
C6: 금년 | D6: 동요일기준 | E6: 목표 | F6: FCST | G6: ACTUAL | H6: 전년 | I6: YOY | J6: 목표 | K6: FCST | L6: ACTUAL | M6: 전년 | N6: YOY | O6: 목표 | P6: FCST | Q6: ACTUAL | R6: 전년 | S6: YOY | T6: 목표 | U6: FCST | V6: ACTUAL | W6: 전년 | X6: YOY | Z6: 목표 | AA6: FCST | AB6: ACTUAL | AC6: 전년 | AD6: YOY | AF6: 목표 | AG6: FCST | AH6: ACTUAL | AI6: 전년 | AJ6: YOY
A7: P:P | C7: 토 | D7: 45962 | E7: =ROUND(E$40*H8/SUM(H$8:H$37,H$47),-6) -> 685000000 | G7: =SUMIFS(INDIRECT("당년!"&$A7),당년!$A:$A,G$1,당년!$B:$B,G$2)+SUMIFS(INDIRECT("당년!"&$A7),당년!$A:$A,G$1,당년!$B:$B,G$3) -> 427008030 | H7: =SUMIFS(INDIRECT("전년!"&$A7),전년!$A:$A,H$1,전년!$B:$B,H$2)+SUMIFS(INDIRECT("전년!"&$A7),전년!$A:$A,H$1,전년!$B:$B,H$3) -> 244553000 | I7: =IFERROR(G7/H7-1,"") -> 0.74607562 | J7: =ROUND(J$40*M8/SUM(M$8:M$37,M$47),-6) -> 372000000 | L7: =SUMIFS(INDIRECT("당년!"&$A7),당년!$A:$A,L$1,당년!$B:$B,L$2)+SUMIFS(INDIRECT("당년!"&$A7),당년!$A:$A,L$1,당년!$B:$B,L$3) -> 681123906 | M7: =SUMIFS(INDIRECT("전년!"&$A7),전년!$A:$A,M$1,전년!$B:$B,M$2)+SUMIFS(INDIRECT("전년!"&$A7),전년!$A:$A,M$1,전년!$B:$B,M$3) -> 197096425 | N7: =IFERROR(L7/M7-1,"") -> 2.4557903 | O7: =ROUND(O$40*R8/SUM(R$8:R$37,R$47),-6) -> 24000000 | P7: 153523110 | Q7: =SUMIFS(INDIRECT("당년!"&$A7),당년!$A:$A,Q$1) -> 35260440 | R7: =SUMIFS(INDIRECT("전년!"&$A7),전년!$A:$A,R$1) -> 73314309 | S7: =IFERROR(Q7/R7-1,"") -> -0.51905105 | T7: =SUM(E7,J7,O7) -> 1081000000 | U7: =SUM(F7,K7,P7) -> 153523110 | V7: =SUM(G7,L7,Q7) -> 1143392376 | W7: =SUM(H7,M7,R7) -> 514963734 | X7: =IFERROR(V7/W7-1,"") -> 1.2203357 | Z7: =ROUND(Z$40*AC8/SUM(AC$8:AC$37,AC$47),-6) -> 451000000 | AA7: 263654100 | AB7: =SUMIFS(INDIRECT("당년!"&$A7),당년!$A:$A,AB$1,당년!$B:$B,AB$2)+SUMIFS(INDIRECT("당년!"&$A7),당년!$A:$A,AB$1,당년!$B:$B,AB$3) -> 478121600 | AC7: =SUMIFS(INDIRECT("전년!"&$A7),전년!$A:$A,AC$1,전년!$B:$B,AC$2)+SUMIFS(INDIRECT("전년!"&$A7),전년!$A:$A,AC$1,전년!$B:$B,AC$3) -> 405294400 | AD7: =IFERROR(AB7/AC7-1,"") -> 0.17968963 | AF7: =SUM(T7,Z7) -> 1532000000 | AG7: =SUM(U7,AA7) -> 417177210 | AH7: =SUM(V7,AB7) -> 1621513976 | AI7: =SUM(W7,AC7) -> 920258134 | AJ7: =IFERROR(AH7/AI7-1,"") -> 0.7620208
A8: Q:Q | C8: 일 | D8: =D7+1 -> 45963 | E8: =ROUND(E$40*H9/SUM(H$8:H$37,H$47),-6) -> 768000000 | G8: =SUMIFS(INDIRECT("당년!"&$A8),당년!$A:$A,G$1,당년!$B:$B,G$2)+SUMIFS(INDIRECT("당년!"&$A8),당년!$A:$A,G$1,당년!$B:$B,G$3) -> 600017030 | H8: =SUMIFS(INDIRECT("전년!"&$A8),전년!$A:$A,H$1,전년!$B:$B,H$2)+SUMIFS(INDIRECT("전년!"&$A8),전년!$A:$A,H$1,전년!$B:$B,H$3) -> 296917110 | I8: =IFERROR(G8/H8-1,"") -> 1.0208234 | J8: =ROUND(J$40*M9/SUM(M$8:M$37,M$47),-6) -> 366000000 | L8: =SUMIFS(INDIRECT("당년!"&$A8),당년!$A:$A,L$1,당년!$B:$B,L$2)+SUMIFS(INDIRECT("당년!"&$A8),당년!$A:$A,L$1,당년!$B:$B,L$3) -> 536227357 | M8: =SUMIFS(INDIRECT("전년!"&$A8),전년!$A:$A,M$1,전년!$B:$B,M$2)+SUMIFS(INDIRECT("전년!"&$A8),전년!$A:$A,M$1,전년!$B:$B,M$3) -> 324298464 | N8: =IFERROR(L8/M8-1,"") -> 0.65349953 | O8: =ROUND(O$40*R9/SUM(R$8:R$37,R$47),-6) -> 25000000 | P8: 62882530 | Q8: =SUMIFS(INDIRECT("당년!"&$A8),당년!$A:$A,Q$1) -> 128903030 | R8: =SUMIFS(INDIRECT("전년!"&$A8),전년!$A:$A,R$1) -> 21968950 | S8: =IFERROR(Q8/R8-1,"") -> 4.8675098 | T8: =SUM(E8,J8,O8) -> 1159000000 | U8: =SUM(F8,K8,P8) -> 62882530 | V8: =SUM(G8,L8,Q8) -> 1265147417 | W8: =SUM(H8,M8,R8) -> 643184524 | X8: =IFERROR(V8/W8-1,"") -> 0.96700538 | Z8: =ROUND(Z$40*AC9/SUM(AC$8:AC$37,AC$47),-6) -> 236000000 | AA8: 300748000 | AB8: =SUMIFS(INDIRECT("당년!"&$A8),당년!$A:$A,AB$1,당년!$B:$B,AB$2)+SUMIFS(INDIRECT("당년!"&$A8),당년!$A:$A,AB$1,당년!$B:$B,AB$3) -> 193710400 | AC8: =SUMIFS(INDIRECT("전년!"&$A8),전년!$A:$A,AC$1,전년!$B:$B,AC$2)+SUMIFS(INDIRECT("전년!"&$A8),전년!$A:$A,AC$1,전년!$B:$B,AC$3) -> 452768700 | AD8: =IFERROR(AB8/AC8-1,"") -> -0.57216477 | AF8: =SUM(T8,Z8) -> 1395000000 | AG8: =SUM(U8,AA8) -> 363630530 | AH8: =SUM(V8,AB8) -> 1458857817 | AI8: =SUM(W8,AC8) -> 1095953224 | AJ8: =IFERROR(AH8/AI8-1,"") -> 0.33113146
A9: R:R | C9: 월 | D9: =D8+1 -> 45964 | E9: =ROUND(E$40*H10/SUM(H$8:H$37,H$47),-6) -> 418000000 | G9: =SUMIFS(INDIRECT("당년!"&$A9),당년!$A:$A,G$1,당년!$B:$B,G$2)+SUMIFS(INDIRECT("당년!"&$A9),당년!$A:$A,G$1,당년!$B:$B,G$3) -> 99801900 | H9: =SUMIFS(INDIRECT("전년!"&$A9),전년!$A:$A,H$1,전년!$B:$B,H$2)+SUMIFS(INDIRECT("전년!"&$A9),전년!$A:$A,H$1,전년!$B:$B,H$3) -> 332906020 | I9: =IFERROR(G9/H9-1,"") -> -0.70020999 | J9: =ROUND(J$40*M10/SUM(M$8:M$37,M$47),-6) -> 330000000 | L9: =SUMIFS(INDIRECT("당년!"&$A9),당년!$A:$A,L$1,당년!$B:$B,L$2)+SUMIFS(INDIRECT("당년!"&$A9),당년!$A:$A,L$1,당년!$B:$B,L$3) -> 344575766 | M9: =SUMIFS(INDIRECT("전년!"&$A9),전년!$A:$A,M$1,전년!$B:$B,M$2)+SUMIFS(INDIRECT("전년!"&$A9),전년!$A:$A,M$1,전년!$B:$B,M$3) -> 319121478 | N9: =IFERROR(L9/M9-1,"") -> 0.079763632 | O9: =ROUND(O$40*R10/SUM(R$8:R$37,R$47),-6) -> 182000000 | P9: 60717900 | Q9: =SUMIFS(INDIRECT("당년!"&$A9),당년!$A:$A,Q$1) -> 167168931 | R9: =SUMIFS(INDIRECT("전년!"&$A9),전년!$A:$A,R$1) -> 23428900 | S9: =IFERROR(Q9/R9-1,"") -> 6.1351592 | T9: =SUM(E9,J9,O9) -> 930000000 | U9: =SUM(F9,K9,P9) -> 60717900 | V9: =SUM(G9,L9,Q9) -> 611546597 | W9: =SUM(H9,M9,R9) -> 675456398 | X9: =IFERROR(V9/W9-1,"") -> -0.094617212 | Z9: =ROUND(Z$40*AC10/SUM(AC$8:AC$37,AC$47),-6) -> 450000000 | AA9: 268628700 | AB9: =SUMIFS(INDIRECT("당년!"&$A9),당년!$A:$A,AB$1,당년!$B:$B,AB$2)+SUMIFS(INDIRECT("당년!"&$A9),당년!$A:$A,AB$1,당년!$B:$B,AB$3) -> 105866000 | AC9: =SUMIFS(INDIRECT("전년!"&$A9),전년!$A:$A,AC$1,전년!$B:$B,AC$2)+SUMIFS(INDIRECT("전년!"&$A9),전년!$A:$A,AC$1,전년!$B:$B,AC$3) -> 236559700 | AD9: =IFERROR(AB9/AC9-1,"") -> -0.55247661 | AF9: =SUM(T9,Z9) -> 1380000000 | AG9: =SUM(U9,AA9) -> 329346600 | AH9: =SUM(V9,AB9) -> 717412597 | AI9: =SUM(W9,AC9) -> 912016098 | AJ9: =IFERROR(AH9/AI9-1,"") -> -0.21337727
A10: S:S | C10: 화 | D10: =D9+1 -> 45965 | E10: =ROUND(E$40*H11/SUM(H$8:H$37,H$47),-6) -> 607000000 | G10: =SUMIFS(INDIRECT("당년!"&$A10),당년!$A:$A,G$1,당년!$B:$B,G$2)+SUMIFS(INDIRECT("당년!"&$A10),당년!$A:$A,G$1,당년!$B:$B,G$3) -> 180435000 | H10: =SUMIFS(INDIRECT("전년!"&$A10),전년!$A:$A,H$1,전년!$B:$B,H$2)+SUMIFS(INDIRECT("전년!"&$A10),전년!$A:$A,H$1,전년!$B:$B,H$3) -> 181309700 | I10: =IFERROR(G10/H10-1,"") -> -0.004824342 | J10: =ROUND(J$40*M11/SUM(M$8:M$37,M$47),-6) -> 318000000 | L10: =SUMIFS(INDIRECT("당년!"&$A10),당년!$A:$A,L$1,당년!$B:$B,L$2)+SUMIFS(INDIRECT("당년!"&$A10),당년!$A:$A,L$1,당년!$B:$B,L$3) -> 416354896 | M10: =SUMIFS(INDIRECT("전년!"&$A10),전년!$A:$A,M$1,전년!$B:$B,M$2)+SUMIFS(INDIRECT("전년!"&$A10),전년!$A:$A,M$1,전년!$B:$B,M$3) -> 288292087 | N10: =IFERROR(L10/M10-1,"") -> 0.44421202 | O10: =ROUND(O$40*R11/SUM(R$8:R$37,R$47),-6) -> 103000000 | P10: 57724500 | Q10: =SUMIFS(INDIRECT("당년!"&$A10),당년!$A:$A,Q$1) -> 114329499 | R10: =SUMIFS(INDIRECT("전년!"&$A10),전년!$A:$A,R$1) -> 167421990 | S10: =IFERROR(Q10/R10-1,"") -> -0.31711779 | T10: =SUM(E10,J10,O10) -> 1028000000 | U10: =SUM(F10,K10,P10) -> 57724500 | V10: =SUM(G10,L10,Q10) -> 711119395 | W10: =SUM(H10,M10,R10) -> 637023777 | X10: =IFERROR(V10/W10-1,"") -> 0.11631531 | Z10: =ROUND(Z$40*AC11/SUM(AC$8:AC$37,AC$47),-6) -> 457000000 | AA10: 654929230 | AB10: =SUMIFS(INDIRECT("당년!"&$A10),당년!$A:$A,AB$1,당년!$B:$B,AB$2)+SUMIFS(INDIRECT("당년!"&$A10),당년!$A:$A,AB$1,당년!$B:$B,AB$3) -> 123082600 | AC10: =SUMIFS(INDIRECT("전년!"&$A10),전년!$A:$A,AC$1,전년!$B:$B,AC$2)+SUMIFS(INDIRECT("전년!"&$A10),전년!$A:$A,AC$1,전년!$B:$B,AC$3) -> 452319100 | AD10: =IFERROR(AB10/AC10-1,"") -> -0.72788547 | AF10: =SUM(T10,Z10) -> 1485000000 | AG10: =SUM(U10,AA10) -> 712653730 | AH10: =SUM(V10,AB10) -> 834201995 | AI10: =SUM(W10,AC10) -> 1089342877 | AJ10: =IFERROR(AH10/AI10-1,"") -> -0.2342154
